2025-09-16 11:46:41,969 - INFO - ================ Application Started ================
2025-09-16 11:46:52,830 - INFO - User 'leot' is attempting to log in.
2025-09-16 11:46:52,985 - INFO - User 'leot' logged in successfully. Assigned groups: ['LCConfidential', 'LCIT']
2025-09-16 11:47:10,270 - INFO - User 'leot' closed the application.
2025-09-16 11:50:19,119 - INFO - ================ Application Started ================
2025-09-16 11:50:25,079 - INFO - User 'leot' is attempting to log in.
2025-09-16 11:50:25,169 - INFO - User 'leot' logged in successfully. Assigned groups: ['LCConfidential', 'LCIT']
2025-09-16 11:58:18,186 - INFO - ================ Application Started ================
2025-09-16 11:58:24,609 - INFO - User 'leot' is attempting to log in.
2025-09-16 11:58:24,695 - INFO - User 'leot' logged in successfully. Assigned groups: ['LCConfidential', 'LCIT']
2025-09-16 11:59:32,279 - INFO - User 'leot' closed the application.
2025-09-16 11:59:34,888 - INFO - ================ Application Started ================
2025-09-16 11:59:40,750 - INFO - User 'leot' is attempting to log in.
2025-09-16 11:59:40,852 - INFO - User 'leot' logged in successfully. Assigned groups: ['LCConfidential', 'LCIT']
2025-09-16 12:02:44,867 - INFO - User 'leot' closed the application.
2025-09-16 12:02:47,564 - INFO - ================ Application Started ================
2025-09-16 12:03:28,324 - INFO - ================ Application Started ================
2025-09-16 12:03:34,924 - INFO - User 'leot' is attempting to log in.
2025-09-16 12:03:35,027 - INFO - User 'leot' logged in successfully. Assigned groups: ['LCConfidential', 'LCIT']
2025-09-16 13:14:03,578 - INFO - ================ Application Started ================
2025-09-16 13:14:12,930 - INFO - User 'leot' is attempting to log in.
2025-09-16 13:14:13,070 - INFO - User 'leot' logged in successfully. Assigned groups: ['LCConfidential', 'LCIT']
2025-09-16 13:14:20,680 - INFO - User 'leot' closed the application.
2025-09-16 13:14:37,605 - INFO - ================ Application Started ================
2025-09-16 13:14:43,615 - INFO - User 'leot' is attempting to log in.
2025-09-16 13:14:43,697 - INFO - User 'leot' logged in successfully. Assigned groups: ['LCConfidential', 'LCIT']
2025-09-16 13:21:51,139 - INFO - User 'leot' closed the application.
2025-09-16 13:24:47,271 - INFO - ================ Application Started ================
2025-09-16 13:24:54,357 - INFO - User 'leot' is attempting to log in.
2025-09-16 13:24:54,467 - INFO - User 'leot' logged in successfully. Assigned groups: ['LCConfidential', 'LCIT']
2025-09-16 13:25:17,618 - INFO - User 'leot' closed the application.
2025-09-16 13:25:17,706 - INFO - ================ Application Started ================
2025-09-16 13:25:25,342 - INFO - User 'leot' is attempting to log in.
2025-09-16 13:25:25,443 - INFO - User 'leot' logged in successfully. Assigned groups: ['LCConfidential', 'LCIT']
2025-09-16 13:26:01,751 - INFO - User 'leot' closed the application.
2025-09-16 13:26:51,286 - INFO - ================ Application Started ================
2025-09-16 13:26:57,343 - INFO - User 'leot' is attempting to log in.
2025-09-16 13:26:57,456 - INFO - User 'leot' logged in successfully. Assigned groups: ['LCConfidential', 'LCIT']
2025-09-16 13:26:57,667 - INFO - '辦法助理' tab selected for the first time. Fetching initial data.
2025-09-16 13:26:57,668 - INFO - User 'leot' is querying assistant 'policy' with: '__GET_WELCOME_MESSAGE__'
2025-09-16 13:27:04,953 - INFO - 'ERP助理' tab selected for the first time. Fetching initial data.
2025-09-16 13:27:05,688 - INFO - 'IT助理' tab selected for the first time. Fetching initial data.
2025-09-16 13:27:17,252 - INFO - Webhook call for assistant 'policy' succeeded.
2025-09-16 13:27:34,652 - INFO - User 'leot' is querying assistant 'policy' with: '我想特休'
2025-09-16 13:27:38,642 - INFO - Webhook call for assistant 'policy' succeeded.
2025-09-16 13:37:08,219 - INFO - User 'leot' closed the application.
2025-09-16 13:37:08,357 - INFO - ================ Application Started ================
2025-09-16 13:37:21,027 - INFO - ================ Application Started ================
2025-09-16 13:37:26,580 - INFO - User 'leot' is attempting to log in.
2025-09-16 13:37:26,661 - INFO - User 'leot' logged in successfully. Assigned groups: ['LCConfidential', 'LCIT']
2025-09-16 13:37:26,950 - INFO - '辦法助理' tab selected for the first time. Fetching initial data.
2025-09-16 13:37:26,951 - INFO - User 'leot' is querying assistant 'policy' with: '__GET_WELCOME_MESSAGE__'
2025-09-16 13:37:44,174 - INFO - Webhook call for assistant 'policy' succeeded.
2025-09-16 13:37:47,252 - INFO - User 'leot' is querying assistant 'policy' with: '我想請特休'
2025-09-16 13:38:00,188 - INFO - Webhook call for assistant 'policy' succeeded.
2025-09-16 13:40:27,200 - INFO - User 'leot' is querying assistant 'policy' with: '你好嗎？'
2025-09-16 13:40:34,411 - INFO - Webhook call for assistant 'policy' succeeded.
2025-09-16 13:42:42,059 - INFO - User 'leot' is querying assistant 'policy' with: '你好嗎？'
2025-09-16 13:42:50,660 - INFO - Webhook call for assistant 'policy' succeeded.
2025-09-16 13:43:16,531 - INFO - User 'leot' is querying assistant 'policy' with: '我遲到了, 怎麼辦?'
2025-09-16 13:43:26,713 - INFO - Webhook call for assistant 'policy' succeeded.
2025-09-16 13:46:48,029 - INFO - 'ERP助理' tab selected for the first time. Fetching initial data.
2025-09-16 13:46:50,685 - INFO - 'IT助理' tab selected for the first time. Fetching initial data.
2025-09-16 13:48:00,579 - INFO - User 'leot' is querying assistant 'policy' with: '我遲到了, 怎麼辦?'
2025-09-16 13:48:27,921 - INFO - Webhook call for assistant 'policy' succeeded.
2025-09-16 13:50:12,745 - INFO - User 'leot' is querying assistant 'policy' with: '我想請特休,要怎麼請'
2025-09-16 13:50:36,578 - INFO - Webhook call for assistant 'policy' succeeded.
2025-09-16 13:54:49,067 - INFO - User 'leot' is querying assistant 'policy' with: '我想請假'
2025-09-16 13:55:19,101 - ERROR - Webhook call for assistant 'policy' failed: HTTPConnectionPool(host='192.168.88.43', port=5678): Read timed out. (read timeout=30)
Traceback (most recent call last):
  File "C:\Users\leot\AppData\Local\Programs\Python\Python313\Lib\site-packages\urllib3\connectionpool.py", line 534, in _make_request
    response = conn.getresponse()
  File "C:\Users\leot\AppData\Local\Programs\Python\Python313\Lib\site-packages\urllib3\connection.py", line 516, in getresponse
    httplib_response = super().getresponse()
  File "C:\Users\leot\AppData\Local\Programs\Python\Python313\Lib\http\client.py", line 1430, in getresponse
    response.begin()
    ~~~~~~~~~~~~~~^^
  File "C:\Users\leot\AppData\Local\Programs\Python\Python313\Lib\http\client.py", line 331, in begin
    version, status, reason = self._read_status()
                              ~~~~~~~~~~~~~~~~~^^
  File "C:\Users\leot\AppData\Local\Programs\Python\Python313\Lib\http\client.py", line 292, in _read_status
    line = str(self.fp.readline(_MAXLINE + 1), "iso-8859-1")
               ~~~~~~~~~~~~~~~~^^^^^^^^^^^^^^
  File "C:\Users\leot\AppData\Local\Programs\Python\Python313\Lib\socket.py", line 719, in readinto
    return self._sock.recv_into(b)
           ~~~~~~~~~~~~~~~~~~~~^^^
TimeoutError: timed out

The above exception was the direct cause of the following exception:

Traceback (most recent call last):
  File "C:\Users\leot\AppData\Local\Programs\Python\Python313\Lib\site-packages\requests\adapters.py", line 667, in send
    resp = conn.urlopen(
        method=request.method,
    ...<9 lines>...
        chunked=chunked,
    )
  File "C:\Users\leot\AppData\Local\Programs\Python\Python313\Lib\site-packages\urllib3\connectionpool.py", line 841, in urlopen
    retries = retries.increment(
        method, url, error=new_e, _pool=self, _stacktrace=sys.exc_info()[2]
    )
  File "C:\Users\leot\AppData\Local\Programs\Python\Python313\Lib\site-packages\urllib3\util\retry.py", line 474, in increment
    raise reraise(type(error), error, _stacktrace)
          ~~~~~~~^^^^^^^^^^^^^^^^^^^^^^^^^^^^^^^^^
  File "C:\Users\leot\AppData\Local\Programs\Python\Python313\Lib\site-packages\urllib3\util\util.py", line 39, in reraise
    raise value
  File "C:\Users\leot\AppData\Local\Programs\Python\Python313\Lib\site-packages\urllib3\connectionpool.py", line 787, in urlopen
    response = self._make_request(
        conn,
    ...<10 lines>...
        **response_kw,
    )
  File "C:\Users\leot\AppData\Local\Programs\Python\Python313\Lib\site-packages\urllib3\connectionpool.py", line 536, in _make_request
    self._raise_timeout(err=e, url=url, timeout_value=read_timeout)
    ~~~~~~~~~~~~~~~~~~~^^^^^^^^^^^^^^^^^^^^^^^^^^^^^^^^^^^^^^^^^^^^
  File "C:\Users\leot\AppData\Local\Programs\Python\Python313\Lib\site-packages\urllib3\connectionpool.py", line 367, in _raise_timeout
    raise ReadTimeoutError(
        self, url, f"Read timed out. (read timeout={timeout_value})"
    ) from err
urllib3.exceptions.ReadTimeoutError: HTTPConnectionPool(host='192.168.88.43', port=5678): Read timed out. (read timeout=30)

During handling of the above exception, another exception occurred:

Traceback (most recent call last):
  File "c:\Users\leot\Desktop\AD_Assistant\main.py", line 238, in perform_assistant_query
    response = requests.post(webhook_url, json=payload, headers={'Content-Type': 'application/json'}, timeout=30)
  File "C:\Users\leot\AppData\Local\Programs\Python\Python313\Lib\site-packages\requests\api.py", line 115, in post
    return request("post", url, data=data, json=json, **kwargs)
  File "C:\Users\leot\AppData\Local\Programs\Python\Python313\Lib\site-packages\requests\api.py", line 59, in request
    return session.request(method=method, url=url, **kwargs)
           ~~~~~~~~~~~~~~~^^^^^^^^^^^^^^^^^^^^^^^^^^^^^^^^^^
  File "C:\Users\leot\AppData\Local\Programs\Python\Python313\Lib\site-packages\requests\sessions.py", line 589, in request
    resp = self.send(prep, **send_kwargs)
  File "C:\Users\leot\AppData\Local\Programs\Python\Python313\Lib\site-packages\requests\sessions.py", line 703, in send
    r = adapter.send(request, **kwargs)
  File "C:\Users\leot\AppData\Local\Programs\Python\Python313\Lib\site-packages\requests\adapters.py", line 713, in send
    raise ReadTimeout(e, request=request)
requests.exceptions.ReadTimeout: HTTPConnectionPool(host='192.168.88.43', port=5678): Read timed out. (read timeout=30)
2025-09-16 13:55:43,132 - INFO - User 'leot' is querying assistant 'policy' with: '我想請特休, 要怎麼請'
2025-09-16 13:56:09,290 - INFO - Webhook call for assistant 'policy' succeeded.
2025-09-16 13:56:53,096 - INFO - User 'leot' closed the application.
2025-09-16 13:56:53,306 - INFO - ================ Application Started ================
2025-09-16 13:58:27,969 - INFO - ================ Application Started ================
2025-09-16 13:58:36,879 - INFO - User 'leot' is attempting to log in.
2025-09-16 13:58:37,022 - ERROR - An exception occurred during login for 'leot': automatic bind not successful - invalidCredentials
Traceback (most recent call last):
  File "c:\Users\leot\Desktop\AD_Assistant\main.py", line 76, in authenticate_ad_and_get_groups
    conn = Connection(server, user=user_principal_name, password=password, auto_bind=True)
  File "C:\Users\leot\AppData\Local\Programs\Python\Python313\Lib\site-packages\ldap3\core\connection.py", line 363, in __init__
    self._do_auto_bind()
    ~~~~~~~~~~~~~~~~~~^^
  File "C:\Users\leot\AppData\Local\Programs\Python\Python313\Lib\site-packages\ldap3\core\connection.py", line 412, in _do_auto_bind
    raise LDAPBindError(error)
ldap3.core.exceptions.LDAPBindError: automatic bind not successful - invalidCredentials
2025-09-16 13:58:43,891 - INFO - User 'leot' is attempting to log in.
2025-09-16 13:58:43,986 - INFO - User 'leot' logged in successfully. Assigned groups: ['LCConfidential', 'LCIT']
2025-09-16 13:58:44,486 - INFO - '辦法助理' tab selected for the first time. Fetching initial data.
2025-09-16 13:58:44,491 - INFO - User 'leot' is querying assistant 'policy' with: '__GET_WELCOME_MESSAGE__'
2025-09-16 13:58:54,309 - INFO - Webhook call for assistant 'policy' succeeded.
2025-09-16 13:59:25,258 - INFO - User 'leot' is querying assistant 'policy' with: '我連續曠職, 公司拿我怎麼辦?'
2025-09-16 13:59:40,208 - INFO - Webhook call for assistant 'policy' succeeded.
2025-09-16 14:00:09,664 - INFO - User 'leot' closed the application.
2025-09-16 14:00:09,912 - INFO - ================ Application Started ================
2025-09-16 14:01:18,140 - INFO - ================ Application Started ================
2025-09-16 14:01:26,398 - INFO - User 'leot' is attempting to log in.
2025-09-16 14:01:26,569 - INFO - User 'leot' logged in successfully. Assigned groups: ['LCConfidential', 'LCIT']
2025-09-16 14:01:26,893 - INFO - '辦法助理' tab selected for the first time. Fetching initial data.
2025-09-16 14:01:26,894 - INFO - User 'leot' is querying assistant 'policy' with: '__GET_WELCOME_MESSAGE__'
2025-09-16 14:01:34,671 - INFO - Webhook call for assistant 'policy' succeeded.
2025-09-16 14:18:54,243 - INFO - User 'leot' closed the application.
2025-09-16 14:18:54,420 - INFO - ================ Application Started ================
2025-09-16 14:19:05,307 - INFO - User 'leot' is attempting to log in.
2025-09-16 14:19:05,351 - ERROR - An exception occurred during login for 'leot': automatic bind not successful - invalidCredentials
Traceback (most recent call last):
  File "c:\Users\leot\Desktop\AD_Assistant\main.py", line 394, in authenticate_ad_and_get_groups
    server = Server(AD_SERVER, port=AD_PORT, use_ssl=USE_SSL, get_info=ALL, tls=tls_config)
           ^^^^^^^^^^^^^^^^^^^^^^^^^^^^^^^^^^^^^^^^^^^^^^^^^^^^^^^^^^^^^^^^^^^^^^^^^^^^^^^
  File "C:\Users\leot\AppData\Local\Programs\Python\Python313\Lib\site-packages\ldap3\core\connection.py", line 363, in __init__
    self._do_auto_bind()
    ~~~~~~~~~~~~~~~~~~^^
  File "C:\Users\leot\AppData\Local\Programs\Python\Python313\Lib\site-packages\ldap3\core\connection.py", line 412, in _do_auto_bind
    raise LDAPBindError(error)
ldap3.core.exceptions.LDAPBindError: automatic bind not successful - invalidCredentials
2025-09-16 14:19:16,186 - INFO - User 'leot' is attempting to log in.
2025-09-16 14:19:16,269 - INFO - User 'leot' logged in successfully. Assigned groups: ['LCConfidential', 'LCIT']
2025-09-16 14:19:27,489 - INFO - User 'leot' closed the application.
2025-09-16 14:19:30,754 - INFO - ================ Application Started ================
2025-09-16 14:20:02,269 - INFO - User 'leot' is attempting to log in.
2025-09-16 14:20:02,422 - INFO - User 'leot' logged in successfully. Assigned groups: ['LCConfidential', 'LCIT']
2025-09-16 14:20:02,907 - INFO - '辦法助理' tab selected for the first time. Fetching initial data.
2025-09-16 14:20:02,907 - INFO - User 'leot' is querying assistant 'policy' with: '__GET_WELCOME_MESSAGE__'
2025-09-16 14:20:22,641 - INFO - Webhook call for assistant 'policy' succeeded.
2025-09-16 14:20:49,325 - INFO - User 'leot' is querying assistant 'policy' with: '我不想幹了, 我要怎麼辦?'
2025-09-16 14:21:09,690 - INFO - Webhook call for assistant 'policy' succeeded.
2025-09-16 14:23:40,987 - INFO - User 'leot' is querying assistant 'policy' with: '我要查蔡存悌的分機'
2025-09-16 14:23:41,286 - INFO - User 'leot' is querying assistant 'policy' with: '我要查蔡存悌的分機'
2025-09-16 14:23:47,545 - INFO - Webhook call for assistant 'policy' succeeded.
2025-09-16 14:23:54,883 - INFO - Webhook call for assistant 'policy' succeeded.
2025-09-16 14:23:58,641 - INFO - User 'leot' is querying assistant 'policy' with: '我要查LEO的分機'
2025-09-16 14:24:28,661 - ERROR - Webhook call for assistant 'policy' failed: HTTPConnectionPool(host='192.168.88.43', port=5678): Read timed out. (read timeout=30)
Traceback (most recent call last):
  File "C:\Users\leot\AppData\Local\Programs\Python\Python313\Lib\site-packages\urllib3\connectionpool.py", line 534, in _make_request
    response = conn.getresponse()
  File "C:\Users\leot\AppData\Local\Programs\Python\Python313\Lib\site-packages\urllib3\connection.py", line 516, in getresponse
    httplib_response = super().getresponse()
  File "C:\Users\leot\AppData\Local\Programs\Python\Python313\Lib\http\client.py", line 1430, in getresponse
    response.begin()
    ~~~~~~~~~~~~~~^^
  File "C:\Users\leot\AppData\Local\Programs\Python\Python313\Lib\http\client.py", line 331, in begin
    version, status, reason = self._read_status()
                              ~~~~~~~~~~~~~~~~~^^
  File "C:\Users\leot\AppData\Local\Programs\Python\Python313\Lib\http\client.py", line 292, in _read_status
    line = str(self.fp.readline(_MAXLINE + 1), "iso-8859-1")
               ~~~~~~~~~~~~~~~~^^^^^^^^^^^^^^
  File "C:\Users\leot\AppData\Local\Programs\Python\Python313\Lib\socket.py", line 719, in readinto
    return self._sock.recv_into(b)
           ~~~~~~~~~~~~~~~~~~~~^^^
TimeoutError: timed out

The above exception was the direct cause of the following exception:

Traceback (most recent call last):
  File "C:\Users\leot\AppData\Local\Programs\Python\Python313\Lib\site-packages\requests\adapters.py", line 667, in send
    resp = conn.urlopen(
        method=request.method,
    ...<9 lines>...
        chunked=chunked,
    )
  File "C:\Users\leot\AppData\Local\Programs\Python\Python313\Lib\site-packages\urllib3\connectionpool.py", line 841, in urlopen
    retries = retries.increment(
        method, url, error=new_e, _pool=self, _stacktrace=sys.exc_info()[2]
    )
  File "C:\Users\leot\AppData\Local\Programs\Python\Python313\Lib\site-packages\urllib3\util\retry.py", line 474, in increment
    raise reraise(type(error), error, _stacktrace)
          ~~~~~~~^^^^^^^^^^^^^^^^^^^^^^^^^^^^^^^^^
  File "C:\Users\leot\AppData\Local\Programs\Python\Python313\Lib\site-packages\urllib3\util\util.py", line 39, in reraise
    raise value
  File "C:\Users\leot\AppData\Local\Programs\Python\Python313\Lib\site-packages\urllib3\connectionpool.py", line 787, in urlopen
    response = self._make_request(
        conn,
    ...<10 lines>...
        **response_kw,
    )
  File "C:\Users\leot\AppData\Local\Programs\Python\Python313\Lib\site-packages\urllib3\connectionpool.py", line 536, in _make_request
    self._raise_timeout(err=e, url=url, timeout_value=read_timeout)
    ~~~~~~~~~~~~~~~~~~~^^^^^^^^^^^^^^^^^^^^^^^^^^^^^^^^^^^^^^^^^^^^
  File "C:\Users\leot\AppData\Local\Programs\Python\Python313\Lib\site-packages\urllib3\connectionpool.py", line 367, in _raise_timeout
    raise ReadTimeoutError(
        self, url, f"Read timed out. (read timeout={timeout_value})"
    ) from err
urllib3.exceptions.ReadTimeoutError: HTTPConnectionPool(host='192.168.88.43', port=5678): Read timed out. (read timeout=30)

During handling of the above exception, another exception occurred:

Traceback (most recent call last):
  File "c:\Users\leot\Desktop\AD_Assistant\main.py", line 239, in perform_assistant_query
    response = requests.post(webhook_url, json=payload, headers={'Content-Type': 'application/json'}, timeout=30)
  File "C:\Users\leot\AppData\Local\Programs\Python\Python313\Lib\site-packages\requests\api.py", line 115, in post
    return request("post", url, data=data, json=json, **kwargs)
  File "C:\Users\leot\AppData\Local\Programs\Python\Python313\Lib\site-packages\requests\api.py", line 59, in request
    return session.request(method=method, url=url, **kwargs)
           ~~~~~~~~~~~~~~~^^^^^^^^^^^^^^^^^^^^^^^^^^^^^^^^^^
  File "C:\Users\leot\AppData\Local\Programs\Python\Python313\Lib\site-packages\requests\sessions.py", line 589, in request
    resp = self.send(prep, **send_kwargs)
  File "C:\Users\leot\AppData\Local\Programs\Python\Python313\Lib\site-packages\requests\sessions.py", line 703, in send
    r = adapter.send(request, **kwargs)
  File "C:\Users\leot\AppData\Local\Programs\Python\Python313\Lib\site-packages\requests\adapters.py", line 713, in send
    raise ReadTimeout(e, request=request)
requests.exceptions.ReadTimeout: HTTPConnectionPool(host='192.168.88.43', port=5678): Read timed out. (read timeout=30)
2025-09-16 14:25:10,626 - INFO - User 'leot' is querying assistant 'policy' with: '我要請購一個料號, 我要怎麼申請?'
2025-09-16 14:25:36,840 - INFO - Webhook call for assistant 'policy' succeeded.
2025-09-16 14:28:04,999 - INFO - User 'leot' is querying assistant 'policy' with: '我要申請料號, 我要怎麼申請?'
2025-09-16 14:28:18,754 - INFO - Webhook call for assistant 'policy' succeeded.
2025-09-16 14:29:22,554 - INFO - 'ERP助理' tab selected for the first time. Fetching initial data.
2025-09-16 14:30:31,303 - INFO - User 'leot' is querying assistant 'policy' with: '我上班途中跌倒了, 有相關的補償嗎?'
2025-09-16 14:30:55,500 - INFO - Webhook call for assistant 'policy' succeeded.
2025-09-16 14:31:52,492 - INFO - User 'leot' closed the application.
2025-09-16 14:31:52,606 - INFO - ================ Application Started ================
2025-09-16 14:31:54,707 - INFO - ================ Application Started ================
2025-09-16 14:31:57,058 - INFO - ================ Application Started ================
2025-09-16 14:32:04,383 - INFO - ================ Application Started ================
2025-09-16 14:32:07,859 - INFO - ================ Application Started ================
2025-09-16 14:32:11,336 - INFO - ================ Application Started ================
2025-09-16 14:40:14,279 - INFO - User 'leot' is attempting to log in.
2025-09-16 14:40:14,450 - INFO - User 'leot' logged in successfully. Assigned groups: ['LCConfidential', 'LCIT']
2025-09-16 14:40:15,100 - INFO - '辦法助理' tab selected for the first time. Fetching initial data.
2025-09-16 14:40:15,102 - INFO - User 'leot' is querying assistant 'policy' with: '__GET_WELCOME_MESSAGE__'
2025-09-16 14:40:34,988 - INFO - Webhook call for assistant 'policy' succeeded.
2025-09-16 14:40:44,191 - INFO - User 'leot' is querying assistant 'policy' with: '我要請假'
2025-09-16 14:41:03,306 - INFO - User 'leot' closed the application.
2025-09-16 14:41:03,650 - INFO - ================ Application Started ================
2025-09-16 14:41:14,210 - ERROR - Webhook call for assistant 'policy' failed: HTTPConnectionPool(host='192.168.88.43', port=5678): Read timed out. (read timeout=30)
Traceback (most recent call last):
  File "C:\Users\leot\AppData\Local\Programs\Python\Python313\Lib\site-packages\urllib3\connectionpool.py", line 534, in _make_request
    response = conn.getresponse()
  File "C:\Users\leot\AppData\Local\Programs\Python\Python313\Lib\site-packages\urllib3\connection.py", line 516, in getresponse
    httplib_response = super().getresponse()
  File "C:\Users\leot\AppData\Local\Programs\Python\Python313\Lib\http\client.py", line 1430, in getresponse
    response.begin()
    ~~~~~~~~~~~~~~^^
  File "C:\Users\leot\AppData\Local\Programs\Python\Python313\Lib\http\client.py", line 331, in begin
    version, status, reason = self._read_status()
                              ~~~~~~~~~~~~~~~~~^^
  File "C:\Users\leot\AppData\Local\Programs\Python\Python313\Lib\http\client.py", line 292, in _read_status
    line = str(self.fp.readline(_MAXLINE + 1), "iso-8859-1")
               ~~~~~~~~~~~~~~~~^^^^^^^^^^^^^^
  File "C:\Users\leot\AppData\Local\Programs\Python\Python313\Lib\socket.py", line 719, in readinto
    return self._sock.recv_into(b)
           ~~~~~~~~~~~~~~~~~~~~^^^
TimeoutError: timed out

The above exception was the direct cause of the following exception:

Traceback (most recent call last):
  File "C:\Users\leot\AppData\Local\Programs\Python\Python313\Lib\site-packages\requests\adapters.py", line 667, in send
    resp = conn.urlopen(
        method=request.method,
    ...<9 lines>...
        chunked=chunked,
    )
  File "C:\Users\leot\AppData\Local\Programs\Python\Python313\Lib\site-packages\urllib3\connectionpool.py", line 841, in urlopen
    retries = retries.increment(
        method, url, error=new_e, _pool=self, _stacktrace=sys.exc_info()[2]
    )
  File "C:\Users\leot\AppData\Local\Programs\Python\Python313\Lib\site-packages\urllib3\util\retry.py", line 474, in increment
    raise reraise(type(error), error, _stacktrace)
          ~~~~~~~^^^^^^^^^^^^^^^^^^^^^^^^^^^^^^^^^
  File "C:\Users\leot\AppData\Local\Programs\Python\Python313\Lib\site-packages\urllib3\util\util.py", line 39, in reraise
    raise value
  File "C:\Users\leot\AppData\Local\Programs\Python\Python313\Lib\site-packages\urllib3\connectionpool.py", line 787, in urlopen
    response = self._make_request(
        conn,
    ...<10 lines>...
        **response_kw,
    )
  File "C:\Users\leot\AppData\Local\Programs\Python\Python313\Lib\site-packages\urllib3\connectionpool.py", line 536, in _make_request
    self._raise_timeout(err=e, url=url, timeout_value=read_timeout)
    ~~~~~~~~~~~~~~~~~~~^^^^^^^^^^^^^^^^^^^^^^^^^^^^^^^^^^^^^^^^^^^^
  File "C:\Users\leot\AppData\Local\Programs\Python\Python313\Lib\site-packages\urllib3\connectionpool.py", line 367, in _raise_timeout
    raise ReadTimeoutError(
        self, url, f"Read timed out. (read timeout={timeout_value})"
    ) from err
urllib3.exceptions.ReadTimeoutError: HTTPConnectionPool(host='192.168.88.43', port=5678): Read timed out. (read timeout=30)

During handling of the above exception, another exception occurred:

Traceback (most recent call last):
  File "c:\Users\leot\Desktop\AD_Assistant\main.py", line 239, in perform_assistant_query
    class LoginWindow(tk.Tk):
                           ^^
  File "C:\Users\leot\AppData\Local\Programs\Python\Python313\Lib\site-packages\requests\api.py", line 115, in post
    return request("post", url, data=data, json=json, **kwargs)
  File "C:\Users\leot\AppData\Local\Programs\Python\Python313\Lib\site-packages\requests\api.py", line 59, in request
    return session.request(method=method, url=url, **kwargs)
           ~~~~~~~~~~~~~~~^^^^^^^^^^^^^^^^^^^^^^^^^^^^^^^^^^
  File "C:\Users\leot\AppData\Local\Programs\Python\Python313\Lib\site-packages\requests\sessions.py", line 589, in request
    resp = self.send(prep, **send_kwargs)
  File "C:\Users\leot\AppData\Local\Programs\Python\Python313\Lib\site-packages\requests\sessions.py", line 703, in send
    r = adapter.send(request, **kwargs)
  File "C:\Users\leot\AppData\Local\Programs\Python\Python313\Lib\site-packages\requests\adapters.py", line 713, in send
    raise ReadTimeout(e, request=request)
requests.exceptions.ReadTimeout: HTTPConnectionPool(host='192.168.88.43', port=5678): Read timed out. (read timeout=30)
2025-09-16 14:41:24,888 - INFO - ================ Application Started ================
2025-09-16 14:41:36,813 - INFO - ================ Application Started ================
2025-09-16 14:41:42,879 - INFO - User 'leot' is attempting to log in.
2025-09-16 14:41:42,976 - INFO - User 'leot' logged in successfully. Groups: ['LCConfidential', 'LCIT']
2025-09-16 14:41:49,521 - INFO - User 'leot' closed the application.
2025-09-16 14:42:13,775 - INFO - ================ Application Started ================
2025-09-16 14:42:19,478 - INFO - User 'leot' is attempting to log in.
2025-09-16 14:42:19,582 - INFO - User 'leot' logged in successfully. Groups: ['LCConfidential', 'LCIT']
2025-09-16 14:42:44,905 - INFO - User 'leot' querying 'policy': '我要查請假規定'
2025-09-16 14:43:12,919 - INFO - Webhook call for 'policy' succeeded.
2025-09-16 14:43:28,615 - INFO - User 'leot' closed the application.
2025-09-16 14:49:08,524 - INFO - ================ Application Started ================
2025-09-16 14:49:16,269 - INFO - User 'leot' is attempting to log in.
2025-09-16 14:49:16,369 - INFO - User 'leot' logged in successfully. Groups: ['LCConfidential', 'LCIT']
2025-09-16 14:49:19,028 - INFO - User 'leot' closed the application.
2025-09-16 14:49:38,719 - INFO - ================ Application Started ================
2025-09-16 14:49:50,589 - INFO - User 'leot' is attempting to log in.
2025-09-16 14:49:50,735 - INFO - User 'leot' logged in successfully. Groups: ['LCConfidential', 'LCIT']
2025-09-16 14:50:18,296 - INFO - User 'leot' querying 'policy': '我要請假'
2025-09-16 14:50:48,340 - ERROR - Webhook call for 'policy' failed: HTTPConnectionPool(host='192.168.88.43', port=5678): Read timed out. (read timeout=30)
Traceback (most recent call last):
  File "C:\Users\leot\AppData\Local\Programs\Python\Python313\Lib\site-packages\urllib3\connectionpool.py", line 534, in _make_request
    response = conn.getresponse()
  File "C:\Users\leot\AppData\Local\Programs\Python\Python313\Lib\site-packages\urllib3\connection.py", line 516, in getresponse
    httplib_response = super().getresponse()
  File "C:\Users\leot\AppData\Local\Programs\Python\Python313\Lib\http\client.py", line 1430, in getresponse
    response.begin()
    ~~~~~~~~~~~~~~^^
  File "C:\Users\leot\AppData\Local\Programs\Python\Python313\Lib\http\client.py", line 331, in begin
    version, status, reason = self._read_status()
                              ~~~~~~~~~~~~~~~~~^^
  File "C:\Users\leot\AppData\Local\Programs\Python\Python313\Lib\http\client.py", line 292, in _read_status
    line = str(self.fp.readline(_MAXLINE + 1), "iso-8859-1")
               ~~~~~~~~~~~~~~~~^^^^^^^^^^^^^^
  File "C:\Users\leot\AppData\Local\Programs\Python\Python313\Lib\socket.py", line 719, in readinto
    return self._sock.recv_into(b)
           ~~~~~~~~~~~~~~~~~~~~^^^
TimeoutError: timed out

The above exception was the direct cause of the following exception:

Traceback (most recent call last):
  File "C:\Users\leot\AppData\Local\Programs\Python\Python313\Lib\site-packages\requests\adapters.py", line 667, in send
    resp = conn.urlopen(
        method=request.method,
    ...<9 lines>...
        chunked=chunked,
    )
  File "C:\Users\leot\AppData\Local\Programs\Python\Python313\Lib\site-packages\urllib3\connectionpool.py", line 841, in urlopen
    retries = retries.increment(
        method, url, error=new_e, _pool=self, _stacktrace=sys.exc_info()[2]
    )
  File "C:\Users\leot\AppData\Local\Programs\Python\Python313\Lib\site-packages\urllib3\util\retry.py", line 474, in increment
    raise reraise(type(error), error, _stacktrace)
          ~~~~~~~^^^^^^^^^^^^^^^^^^^^^^^^^^^^^^^^^
  File "C:\Users\leot\AppData\Local\Programs\Python\Python313\Lib\site-packages\urllib3\util\util.py", line 39, in reraise
    raise value
  File "C:\Users\leot\AppData\Local\Programs\Python\Python313\Lib\site-packages\urllib3\connectionpool.py", line 787, in urlopen
    response = self._make_request(
        conn,
    ...<10 lines>...
        **response_kw,
    )
  File "C:\Users\leot\AppData\Local\Programs\Python\Python313\Lib\site-packages\urllib3\connectionpool.py", line 536, in _make_request
    self._raise_timeout(err=e, url=url, timeout_value=read_timeout)
    ~~~~~~~~~~~~~~~~~~~^^^^^^^^^^^^^^^^^^^^^^^^^^^^^^^^^^^^^^^^^^^^
  File "C:\Users\leot\AppData\Local\Programs\Python\Python313\Lib\site-packages\urllib3\connectionpool.py", line 367, in _raise_timeout
    raise ReadTimeoutError(
        self, url, f"Read timed out. (read timeout={timeout_value})"
    ) from err
urllib3.exceptions.ReadTimeoutError: HTTPConnectionPool(host='192.168.88.43', port=5678): Read timed out. (read timeout=30)

During handling of the above exception, another exception occurred:

Traceback (most recent call last):
  File "c:\Users\leot\Desktop\AD_Assistant\main.py", line 216, in perform_assistant_query
    response = requests.post(webhook_url, json=payload, headers={'Content-Type': 'application/json'}, timeout=30)
  File "C:\Users\leot\AppData\Local\Programs\Python\Python313\Lib\site-packages\requests\api.py", line 115, in post
    return request("post", url, data=data, json=json, **kwargs)
  File "C:\Users\leot\AppData\Local\Programs\Python\Python313\Lib\site-packages\requests\api.py", line 59, in request
    return session.request(method=method, url=url, **kwargs)
           ~~~~~~~~~~~~~~~^^^^^^^^^^^^^^^^^^^^^^^^^^^^^^^^^^
  File "C:\Users\leot\AppData\Local\Programs\Python\Python313\Lib\site-packages\requests\sessions.py", line 589, in request
    resp = self.send(prep, **send_kwargs)
  File "C:\Users\leot\AppData\Local\Programs\Python\Python313\Lib\site-packages\requests\sessions.py", line 703, in send
    r = adapter.send(request, **kwargs)
  File "C:\Users\leot\AppData\Local\Programs\Python\Python313\Lib\site-packages\requests\adapters.py", line 713, in send
    raise ReadTimeout(e, request=request)
requests.exceptions.ReadTimeout: HTTPConnectionPool(host='192.168.88.43', port=5678): Read timed out. (read timeout=30)
2025-09-16 15:00:15,325 - INFO - User 'leot' closed the application.
2025-09-16 15:01:27,330 - INFO - ================ Application Started ================
2025-09-16 15:01:34,113 - INFO - User 'leot' is attempting to log in.
2025-09-16 15:01:34,216 - INFO - User 'leot' logged in successfully. Groups: ['LCConfidential', 'LCIT']
2025-09-16 15:01:40,716 - INFO - User 'leot' closed the application.
2025-09-16 15:03:08,781 - INFO - ================ Application Started ================
2025-09-16 15:03:16,379 - INFO - User 'leot' is attempting to log in.
2025-09-16 15:03:16,466 - INFO - User 'leot' logged in successfully. Groups: ['LCConfidential', 'LCIT']
2025-09-16 15:03:51,946 - INFO - User 'leot' querying 'policy': '我受傷了, 不能上班怎麼辦?'
2025-09-16 15:04:16,805 - INFO - Webhook call for 'policy' succeeded.
2025-09-16 15:04:41,748 - INFO - User 'leot' querying 'policy': '我因公受傷, 不能上班怎麼辦?'
2025-09-16 15:05:11,781 - ERROR - Webhook call for 'policy' failed: HTTPConnectionPool(host='192.168.88.43', port=5678): Read timed out. (read timeout=30)
Traceback (most recent call last):
  File "C:\Users\leot\AppData\Local\Programs\Python\Python313\Lib\site-packages\urllib3\connectionpool.py", line 534, in _make_request
    response = conn.getresponse()
  File "C:\Users\leot\AppData\Local\Programs\Python\Python313\Lib\site-packages\urllib3\connection.py", line 516, in getresponse
    httplib_response = super().getresponse()
  File "C:\Users\leot\AppData\Local\Programs\Python\Python313\Lib\http\client.py", line 1430, in getresponse
    response.begin()
    ~~~~~~~~~~~~~~^^
  File "C:\Users\leot\AppData\Local\Programs\Python\Python313\Lib\http\client.py", line 331, in begin
    version, status, reason = self._read_status()
                              ~~~~~~~~~~~~~~~~~^^
  File "C:\Users\leot\AppData\Local\Programs\Python\Python313\Lib\http\client.py", line 292, in _read_status
    line = str(self.fp.readline(_MAXLINE + 1), "iso-8859-1")
               ~~~~~~~~~~~~~~~~^^^^^^^^^^^^^^
  File "C:\Users\leot\AppData\Local\Programs\Python\Python313\Lib\socket.py", line 719, in readinto
    return self._sock.recv_into(b)
           ~~~~~~~~~~~~~~~~~~~~^^^
TimeoutError: timed out

The above exception was the direct cause of the following exception:

Traceback (most recent call last):
  File "C:\Users\leot\AppData\Local\Programs\Python\Python313\Lib\site-packages\requests\adapters.py", line 667, in send
    resp = conn.urlopen(
        method=request.method,
    ...<9 lines>...
        chunked=chunked,
    )
  File "C:\Users\leot\AppData\Local\Programs\Python\Python313\Lib\site-packages\urllib3\connectionpool.py", line 841, in urlopen
    retries = retries.increment(
        method, url, error=new_e, _pool=self, _stacktrace=sys.exc_info()[2]
    )
  File "C:\Users\leot\AppData\Local\Programs\Python\Python313\Lib\site-packages\urllib3\util\retry.py", line 474, in increment
    raise reraise(type(error), error, _stacktrace)
          ~~~~~~~^^^^^^^^^^^^^^^^^^^^^^^^^^^^^^^^^
  File "C:\Users\leot\AppData\Local\Programs\Python\Python313\Lib\site-packages\urllib3\util\util.py", line 39, in reraise
    raise value
  File "C:\Users\leot\AppData\Local\Programs\Python\Python313\Lib\site-packages\urllib3\connectionpool.py", line 787, in urlopen
    response = self._make_request(
        conn,
    ...<10 lines>...
        **response_kw,
    )
  File "C:\Users\leot\AppData\Local\Programs\Python\Python313\Lib\site-packages\urllib3\connectionpool.py", line 536, in _make_request
    self._raise_timeout(err=e, url=url, timeout_value=read_timeout)
    ~~~~~~~~~~~~~~~~~~~^^^^^^^^^^^^^^^^^^^^^^^^^^^^^^^^^^^^^^^^^^^^
  File "C:\Users\leot\AppData\Local\Programs\Python\Python313\Lib\site-packages\urllib3\connectionpool.py", line 367, in _raise_timeout
    raise ReadTimeoutError(
        self, url, f"Read timed out. (read timeout={timeout_value})"
    ) from err
urllib3.exceptions.ReadTimeoutError: HTTPConnectionPool(host='192.168.88.43', port=5678): Read timed out. (read timeout=30)

During handling of the above exception, another exception occurred:

Traceback (most recent call last):
  File "c:\Users\leot\Desktop\AD_Assistant\main.py", line 186, in perform_assistant_query
    response = requests.post(webhook_url, json=payload, headers={'Content-Type': 'application/json'}, timeout=30)
  File "C:\Users\leot\AppData\Local\Programs\Python\Python313\Lib\site-packages\requests\api.py", line 115, in post
    return request("post", url, data=data, json=json, **kwargs)
  File "C:\Users\leot\AppData\Local\Programs\Python\Python313\Lib\site-packages\requests\api.py", line 59, in request
    return session.request(method=method, url=url, **kwargs)
           ~~~~~~~~~~~~~~~^^^^^^^^^^^^^^^^^^^^^^^^^^^^^^^^^^
  File "C:\Users\leot\AppData\Local\Programs\Python\Python313\Lib\site-packages\requests\sessions.py", line 589, in request
    resp = self.send(prep, **send_kwargs)
  File "C:\Users\leot\AppData\Local\Programs\Python\Python313\Lib\site-packages\requests\sessions.py", line 703, in send
    r = adapter.send(request, **kwargs)
  File "C:\Users\leot\AppData\Local\Programs\Python\Python313\Lib\site-packages\requests\adapters.py", line 713, in send
    raise ReadTimeout(e, request=request)
requests.exceptions.ReadTimeout: HTTPConnectionPool(host='192.168.88.43', port=5678): Read timed out. (read timeout=30)
2025-09-16 15:08:58,499 - INFO - User 'leot' querying 'policy': '我因公受傷, 不能上班怎麼辦?'
2025-09-16 15:09:24,972 - INFO - Webhook call for 'policy' succeeded.
2025-09-16 15:11:21,190 - INFO - User 'leot' querying 'policy': '我下班要去跟客戶喝花酒, 交際費可以申請嗎?'
2025-09-16 15:11:38,268 - INFO - Webhook call for 'policy' succeeded.
2025-09-16 15:13:09,704 - INFO - User 'leot' querying 'policy': '我的交際費為3千1元, 這個會簽到哪?'
2025-09-16 15:13:22,960 - INFO - Webhook call for 'policy' succeeded.
2025-09-16 15:23:34,455 - INFO - User 'leot' closed the application.
2025-09-16 15:23:36,849 - INFO - ================ Application Started ================
2025-09-16 15:23:45,464 - INFO - User 'leot' is attempting to log in.
2025-09-16 15:23:45,624 - INFO - User 'leot' logged in successfully. Groups: ['LCConfidential', 'LCIT']
2025-09-16 15:23:49,046 - INFO - User 'leot' closed application.
2025-09-16 15:23:50,869 - INFO - ================ Application Started ================
2025-09-16 15:24:26,362 - INFO - ================ Application Started ================
2025-09-16 15:24:32,019 - INFO - User 'leot' is attempting to log in.
2025-09-16 15:24:32,116 - INFO - User 'leot' logged in successfully. Groups: ['LCConfidential', 'LCIT']
2025-09-16 15:26:15,651 - INFO - User 'leot' closed application.
2025-09-16 15:26:21,997 - INFO - ================ Application Started ================
2025-09-16 15:26:27,992 - INFO - User 'leot' is attempting to log in.
2025-09-16 15:26:28,107 - INFO - User 'leot' logged in successfully. Groups: ['LCConfidential', 'LCIT']
2025-09-16 15:26:55,966 - INFO - User 'leot' querying 'policy': '我快死了, 公司有相補償嗎?'
2025-09-16 15:27:25,973 - ERROR - Webhook call for 'policy' failed: HTTPConnectionPool(host='192.168.88.43', port=5678): Read timed out. (read timeout=30)
Traceback (most recent call last):
  File "C:\Users\leot\AppData\Local\Programs\Python\Python313\Lib\site-packages\urllib3\connectionpool.py", line 534, in _make_request
    response = conn.getresponse()
  File "C:\Users\leot\AppData\Local\Programs\Python\Python313\Lib\site-packages\urllib3\connection.py", line 516, in getresponse
    httplib_response = super().getresponse()
  File "C:\Users\leot\AppData\Local\Programs\Python\Python313\Lib\http\client.py", line 1430, in getresponse
    response.begin()
    ~~~~~~~~~~~~~~^^
  File "C:\Users\leot\AppData\Local\Programs\Python\Python313\Lib\http\client.py", line 331, in begin
    version, status, reason = self._read_status()
                              ~~~~~~~~~~~~~~~~~^^
  File "C:\Users\leot\AppData\Local\Programs\Python\Python313\Lib\http\client.py", line 292, in _read_status
    line = str(self.fp.readline(_MAXLINE + 1), "iso-8859-1")
               ~~~~~~~~~~~~~~~~^^^^^^^^^^^^^^
  File "C:\Users\leot\AppData\Local\Programs\Python\Python313\Lib\socket.py", line 719, in readinto
    return self._sock.recv_into(b)
           ~~~~~~~~~~~~~~~~~~~~^^^
TimeoutError: timed out

The above exception was the direct cause of the following exception:

Traceback (most recent call last):
  File "C:\Users\leot\AppData\Local\Programs\Python\Python313\Lib\site-packages\requests\adapters.py", line 667, in send
    resp = conn.urlopen(
        method=request.method,
    ...<9 lines>...
        chunked=chunked,
    )
  File "C:\Users\leot\AppData\Local\Programs\Python\Python313\Lib\site-packages\urllib3\connectionpool.py", line 841, in urlopen
    retries = retries.increment(
        method, url, error=new_e, _pool=self, _stacktrace=sys.exc_info()[2]
    )
  File "C:\Users\leot\AppData\Local\Programs\Python\Python313\Lib\site-packages\urllib3\util\retry.py", line 474, in increment
    raise reraise(type(error), error, _stacktrace)
          ~~~~~~~^^^^^^^^^^^^^^^^^^^^^^^^^^^^^^^^^
  File "C:\Users\leot\AppData\Local\Programs\Python\Python313\Lib\site-packages\urllib3\util\util.py", line 39, in reraise
    raise value
  File "C:\Users\leot\AppData\Local\Programs\Python\Python313\Lib\site-packages\urllib3\connectionpool.py", line 787, in urlopen
    response = self._make_request(
        conn,
    ...<10 lines>...
        **response_kw,
    )
  File "C:\Users\leot\AppData\Local\Programs\Python\Python313\Lib\site-packages\urllib3\connectionpool.py", line 536, in _make_request
    self._raise_timeout(err=e, url=url, timeout_value=read_timeout)
    ~~~~~~~~~~~~~~~~~~~^^^^^^^^^^^^^^^^^^^^^^^^^^^^^^^^^^^^^^^^^^^^
  File "C:\Users\leot\AppData\Local\Programs\Python\Python313\Lib\site-packages\urllib3\connectionpool.py", line 367, in _raise_timeout
    raise ReadTimeoutError(
        self, url, f"Read timed out. (read timeout={timeout_value})"
    ) from err
urllib3.exceptions.ReadTimeoutError: HTTPConnectionPool(host='192.168.88.43', port=5678): Read timed out. (read timeout=30)

During handling of the above exception, another exception occurred:

Traceback (most recent call last):
  File "c:\Users\leot\Desktop\AD_Assistant\main.py", line 198, in perform_assistant_query
    response = requests.post(webhook_url, json=payload, headers={'Content-Type': 'application/json'}, timeout=30)
  File "C:\Users\leot\AppData\Local\Programs\Python\Python313\Lib\site-packages\requests\api.py", line 115, in post
    return request("post", url, data=data, json=json, **kwargs)
  File "C:\Users\leot\AppData\Local\Programs\Python\Python313\Lib\site-packages\requests\api.py", line 59, in request
    return session.request(method=method, url=url, **kwargs)
           ~~~~~~~~~~~~~~~^^^^^^^^^^^^^^^^^^^^^^^^^^^^^^^^^^
  File "C:\Users\leot\AppData\Local\Programs\Python\Python313\Lib\site-packages\requests\sessions.py", line 589, in request
    resp = self.send(prep, **send_kwargs)
  File "C:\Users\leot\AppData\Local\Programs\Python\Python313\Lib\site-packages\requests\sessions.py", line 703, in send
    r = adapter.send(request, **kwargs)
  File "C:\Users\leot\AppData\Local\Programs\Python\Python313\Lib\site-packages\requests\adapters.py", line 713, in send
    raise ReadTimeout(e, request=request)
requests.exceptions.ReadTimeout: HTTPConnectionPool(host='192.168.88.43', port=5678): Read timed out. (read timeout=30)
2025-09-16 15:28:15,769 - INFO - User 'leot' querying 'policy': '我上班途中受傷, 公司有補償嗎?'
2025-09-16 15:28:41,052 - INFO - Webhook call for 'policy' succeeded.
2025-09-16 15:29:38,161 - INFO - User 'leot' querying 'policy': '我外出時受傷, 可以申請什麼補助?'
2025-09-16 15:29:45,923 - INFO - Webhook call for 'policy' succeeded.
2025-09-16 15:30:06,489 - INFO - User 'leot' querying 'policy': '我因公外出或出差時受傷, 可以申請什麼補助?'
2025-09-16 15:30:17,762 - INFO - Webhook call for 'policy' succeeded.
2025-09-16 15:30:36,375 - INFO - User 'leot' querying 'policy': '我因公外出或出差時受傷怎麼辦?'
2025-09-16 15:30:43,823 - INFO - Webhook call for 'policy' succeeded.
2025-09-16 15:33:58,884 - INFO - User 'leot' querying 'policy': '我因公外出或出差時受傷怎麼辦?'
2025-09-16 15:34:17,823 - INFO - Webhook call for 'policy' succeeded.
2025-09-16 15:34:51,273 - INFO - User 'leot' closed application.
2025-09-16 15:38:56,256 - INFO - ================ Application Started ================
2025-09-16 15:39:02,301 - INFO - User 'leot' is attempting to log in.
2025-09-16 15:39:02,389 - INFO - User 'leot' logged in successfully. Groups: ['LCConfidential', 'LCIT']
2025-09-16 15:39:24,677 - INFO - User 'leot' querying 'policy': '我想請病假'
2025-09-16 15:39:54,692 - ERROR - Webhook call for 'policy' failed: HTTPConnectionPool(host='192.168.88.43', port=5678): Read timed out. (read timeout=30)
Traceback (most recent call last):
  File "C:\Users\leot\AppData\Local\Programs\Python\Python313\Lib\site-packages\urllib3\connectionpool.py", line 534, in _make_request
    response = conn.getresponse()
  File "C:\Users\leot\AppData\Local\Programs\Python\Python313\Lib\site-packages\urllib3\connection.py", line 516, in getresponse
    httplib_response = super().getresponse()
  File "C:\Users\leot\AppData\Local\Programs\Python\Python313\Lib\http\client.py", line 1430, in getresponse
    response.begin()
    ~~~~~~~~~~~~~~^^
  File "C:\Users\leot\AppData\Local\Programs\Python\Python313\Lib\http\client.py", line 331, in begin
    version, status, reason = self._read_status()
                              ~~~~~~~~~~~~~~~~~^^
  File "C:\Users\leot\AppData\Local\Programs\Python\Python313\Lib\http\client.py", line 292, in _read_status
    line = str(self.fp.readline(_MAXLINE + 1), "iso-8859-1")
               ~~~~~~~~~~~~~~~~^^^^^^^^^^^^^^
  File "C:\Users\leot\AppData\Local\Programs\Python\Python313\Lib\socket.py", line 719, in readinto
    return self._sock.recv_into(b)
           ~~~~~~~~~~~~~~~~~~~~^^^
TimeoutError: timed out

The above exception was the direct cause of the following exception:

Traceback (most recent call last):
  File "C:\Users\leot\AppData\Local\Programs\Python\Python313\Lib\site-packages\requests\adapters.py", line 667, in send
    resp = conn.urlopen(
        method=request.method,
    ...<9 lines>...
        chunked=chunked,
    )
  File "C:\Users\leot\AppData\Local\Programs\Python\Python313\Lib\site-packages\urllib3\connectionpool.py", line 841, in urlopen
    retries = retries.increment(
        method, url, error=new_e, _pool=self, _stacktrace=sys.exc_info()[2]
    )
  File "C:\Users\leot\AppData\Local\Programs\Python\Python313\Lib\site-packages\urllib3\util\retry.py", line 474, in increment
    raise reraise(type(error), error, _stacktrace)
          ~~~~~~~^^^^^^^^^^^^^^^^^^^^^^^^^^^^^^^^^
  File "C:\Users\leot\AppData\Local\Programs\Python\Python313\Lib\site-packages\urllib3\util\util.py", line 39, in reraise
    raise value
  File "C:\Users\leot\AppData\Local\Programs\Python\Python313\Lib\site-packages\urllib3\connectionpool.py", line 787, in urlopen
    response = self._make_request(
        conn,
    ...<10 lines>...
        **response_kw,
    )
  File "C:\Users\leot\AppData\Local\Programs\Python\Python313\Lib\site-packages\urllib3\connectionpool.py", line 536, in _make_request
    self._raise_timeout(err=e, url=url, timeout_value=read_timeout)
    ~~~~~~~~~~~~~~~~~~~^^^^^^^^^^^^^^^^^^^^^^^^^^^^^^^^^^^^^^^^^^^^
  File "C:\Users\leot\AppData\Local\Programs\Python\Python313\Lib\site-packages\urllib3\connectionpool.py", line 367, in _raise_timeout
    raise ReadTimeoutError(
        self, url, f"Read timed out. (read timeout={timeout_value})"
    ) from err
urllib3.exceptions.ReadTimeoutError: HTTPConnectionPool(host='192.168.88.43', port=5678): Read timed out. (read timeout=30)

During handling of the above exception, another exception occurred:

Traceback (most recent call last):
  File "c:\Users\leot\Desktop\AD_Assistant\main.py", line 199, in perform_assistant_query
    response = requests.post(webhook_url, json=payload, headers={'Content-Type': 'application/json'}, timeout=30)
  File "C:\Users\leot\AppData\Local\Programs\Python\Python313\Lib\site-packages\requests\api.py", line 115, in post
    return request("post", url, data=data, json=json, **kwargs)
  File "C:\Users\leot\AppData\Local\Programs\Python\Python313\Lib\site-packages\requests\api.py", line 59, in request
    return session.request(method=method, url=url, **kwargs)
           ~~~~~~~~~~~~~~~^^^^^^^^^^^^^^^^^^^^^^^^^^^^^^^^^^
  File "C:\Users\leot\AppData\Local\Programs\Python\Python313\Lib\site-packages\requests\sessions.py", line 589, in request
    resp = self.send(prep, **send_kwargs)
  File "C:\Users\leot\AppData\Local\Programs\Python\Python313\Lib\site-packages\requests\sessions.py", line 703, in send
    r = adapter.send(request, **kwargs)
  File "C:\Users\leot\AppData\Local\Programs\Python\Python313\Lib\site-packages\requests\adapters.py", line 713, in send
    raise ReadTimeout(e, request=request)
requests.exceptions.ReadTimeout: HTTPConnectionPool(host='192.168.88.43', port=5678): Read timed out. (read timeout=30)
2025-09-16 15:40:43,168 - INFO - User 'leot' querying 'policy': '我想請病假'
2025-09-16 15:41:06,983 - INFO - Webhook call for 'policy' succeeded.
2025-09-16 15:41:59,628 - INFO - User 'leot' closed application.
2025-09-16 16:57:51,254 - INFO - ================ Application Started ================
2025-09-16 16:58:00,854 - INFO - User 'leot' is attempting to log in.
2025-09-16 16:58:00,953 - INFO - User 'leot' logged in successfully. Groups: ['LCConfidential', 'LCIT']
2025-09-16 16:59:12,211 - INFO - User 'leot' querying 'policy': '交際費管理辦法中是否有關定參與者上層主管也審核?'
2025-09-16 16:59:39,345 - INFO - Webhook call for 'policy' succeeded.
2025-09-16 17:10:54,649 - INFO - User 'leot' closed application.
2025-09-17 11:50:50,515 - INFO - ================ Application Started ================
2025-09-17 12:56:11,444 - INFO - ================ Application Started ================
2025-09-17 12:56:17,940 - INFO - User 'leot' is attempting to log in.
2025-09-17 12:56:18,132 - INFO - User 'leot' logged in successfully. Groups: ['LCConfidential', 'LCIT']
2025-09-17 12:56:26,937 - INFO - User 'leot' closed application.
2025-09-17 12:58:20,912 - INFO - ================ Application Started ================
2025-09-17 12:58:43,142 - INFO - ================ Application Started ================
2025-09-17 12:59:51,961 - INFO - ================ Application Started ================
2025-09-17 13:00:35,899 - INFO - ================ Application Started ================
2025-09-17 13:01:17,071 - INFO - ================ Application Started ================
2025-09-17 13:05:19,767 - INFO - ================ Application Started ================
2025-09-17 13:05:30,910 - INFO - User 'leot' is attempting to log in.
2025-09-17 13:05:30,999 - INFO - User 'leot' logged in successfully. Groups: ['LCConfidential', 'LCIT']
2025-09-17 13:05:40,741 - INFO - User 'leot' closed application.
2025-09-17 13:06:13,164 - INFO - ================ Application Started ================
2025-09-17 13:06:20,348 - INFO - User 'leot' is attempting to log in.
2025-09-17 13:06:20,592 - INFO - User 'leot' logged in successfully. Groups: ['LCConfidential', 'LCIT']
2025-09-17 13:06:24,983 - INFO - User 'leot' closed application.
2025-09-17 13:07:00,188 - INFO - ================ Application Started ================
2025-09-17 13:07:06,809 - INFO - User 'leot' is attempting to log in.
2025-09-17 13:07:06,947 - INFO - User 'leot' logged in successfully. Groups: ['LCConfidential', 'LCIT']
2025-09-17 13:07:33,808 - INFO - User 'leot' closed application.
2025-09-17 13:09:08,739 - INFO - ================ Application Started ================
2025-09-17 13:09:14,918 - INFO - User 'leot' is attempting to log in.
2025-09-17 13:09:15,113 - INFO - User 'leot' logged in successfully. Groups: ['LCConfidential', 'LCIT']
2025-09-17 13:09:30,652 - INFO - User 'leot' closed application.
2025-09-17 13:50:49,738 - INFO - ================ Application Started ================
2025-09-17 13:51:02,557 - INFO - User 'leot' is attempting to log in.
2025-09-17 13:51:02,684 - INFO - User 'leot' logged in successfully. Groups: ['LCConfidential', 'LCIT']
2025-09-17 13:51:35,396 - INFO - User 'leot' querying 'erp': '請問我要收一個貨要怎麼做?'
2025-09-17 13:51:59,194 - INFO - Webhook call for 'erp' succeeded.
2025-09-17 13:53:53,721 - INFO - User 'leot' querying 'erp': '採買的貨送到了要怎麼處理?'
2025-09-17 13:54:11,740 - INFO - Webhook call for 'erp' succeeded.
2025-09-17 13:55:07,041 - INFO - User 'leot' querying 'erp': '請說明開立採購單之動作'
2025-09-17 13:55:26,427 - INFO - Webhook call for 'erp' succeeded.
2025-09-17 13:55:52,311 - INFO - User 'leot' querying 'erp': '採購收貨業為何?'
2025-09-17 13:56:16,878 - INFO - Webhook call for 'erp' succeeded.
2025-09-17 13:56:51,113 - INFO - User 'leot' querying 'erp': '建立退貨請求單的步驟'
2025-09-17 13:57:12,550 - INFO - Webhook call for 'erp' succeeded.
2025-09-17 13:58:06,760 - INFO - User 'leot' querying 'erp': '我要做採購退貨要怎麼做?'
2025-09-17 13:58:36,777 - ERROR - Webhook call for 'erp' failed: HTTPConnectionPool(host='192.168.88.43', port=5678): Read timed out. (read timeout=30)
Traceback (most recent call last):
  File "C:\Users\leot\AppData\Local\Programs\Python\Python313\Lib\site-packages\urllib3\connectionpool.py", line 534, in _make_request
    response = conn.getresponse()
  File "C:\Users\leot\AppData\Local\Programs\Python\Python313\Lib\site-packages\urllib3\connection.py", line 516, in getresponse
    httplib_response = super().getresponse()
  File "C:\Users\leot\AppData\Local\Programs\Python\Python313\Lib\http\client.py", line 1430, in getresponse
    response.begin()
    ~~~~~~~~~~~~~~^^
  File "C:\Users\leot\AppData\Local\Programs\Python\Python313\Lib\http\client.py", line 331, in begin
    version, status, reason = self._read_status()
                              ~~~~~~~~~~~~~~~~~^^
  File "C:\Users\leot\AppData\Local\Programs\Python\Python313\Lib\http\client.py", line 292, in _read_status
    line = str(self.fp.readline(_MAXLINE + 1), "iso-8859-1")
               ~~~~~~~~~~~~~~~~^^^^^^^^^^^^^^
  File "C:\Users\leot\AppData\Local\Programs\Python\Python313\Lib\socket.py", line 719, in readinto
    return self._sock.recv_into(b)
           ~~~~~~~~~~~~~~~~~~~~^^^
TimeoutError: timed out

The above exception was the direct cause of the following exception:

Traceback (most recent call last):
  File "C:\Users\leot\AppData\Local\Programs\Python\Python313\Lib\site-packages\requests\adapters.py", line 667, in send
    resp = conn.urlopen(
        method=request.method,
    ...<9 lines>...
        chunked=chunked,
    )
  File "C:\Users\leot\AppData\Local\Programs\Python\Python313\Lib\site-packages\urllib3\connectionpool.py", line 841, in urlopen
    retries = retries.increment(
        method, url, error=new_e, _pool=self, _stacktrace=sys.exc_info()[2]
    )
  File "C:\Users\leot\AppData\Local\Programs\Python\Python313\Lib\site-packages\urllib3\util\retry.py", line 474, in increment
    raise reraise(type(error), error, _stacktrace)
          ~~~~~~~^^^^^^^^^^^^^^^^^^^^^^^^^^^^^^^^^
  File "C:\Users\leot\AppData\Local\Programs\Python\Python313\Lib\site-packages\urllib3\util\util.py", line 39, in reraise
    raise value
  File "C:\Users\leot\AppData\Local\Programs\Python\Python313\Lib\site-packages\urllib3\connectionpool.py", line 787, in urlopen
    response = self._make_request(
        conn,
    ...<10 lines>...
        **response_kw,
    )
  File "C:\Users\leot\AppData\Local\Programs\Python\Python313\Lib\site-packages\urllib3\connectionpool.py", line 536, in _make_request
    self._raise_timeout(err=e, url=url, timeout_value=read_timeout)
    ~~~~~~~~~~~~~~~~~~~^^^^^^^^^^^^^^^^^^^^^^^^^^^^^^^^^^^^^^^^^^^^
  File "C:\Users\leot\AppData\Local\Programs\Python\Python313\Lib\site-packages\urllib3\connectionpool.py", line 367, in _raise_timeout
    raise ReadTimeoutError(
        self, url, f"Read timed out. (read timeout={timeout_value})"
    ) from err
urllib3.exceptions.ReadTimeoutError: HTTPConnectionPool(host='192.168.88.43', port=5678): Read timed out. (read timeout=30)

During handling of the above exception, another exception occurred:

Traceback (most recent call last):
  File "c:\Users\leot\Desktop\AD_Assistant\main.py", line 210, in perform_assistant_query
    response = requests.post(webhook_url, json=payload, headers={'Content-Type': 'application/json'}, timeout=30)
  File "C:\Users\leot\AppData\Local\Programs\Python\Python313\Lib\site-packages\requests\api.py", line 115, in post
    return request("post", url, data=data, json=json, **kwargs)
  File "C:\Users\leot\AppData\Local\Programs\Python\Python313\Lib\site-packages\requests\api.py", line 59, in request
    return session.request(method=method, url=url, **kwargs)
           ~~~~~~~~~~~~~~~^^^^^^^^^^^^^^^^^^^^^^^^^^^^^^^^^^
  File "C:\Users\leot\AppData\Local\Programs\Python\Python313\Lib\site-packages\requests\sessions.py", line 589, in request
    resp = self.send(prep, **send_kwargs)
  File "C:\Users\leot\AppData\Local\Programs\Python\Python313\Lib\site-packages\requests\sessions.py", line 703, in send
    r = adapter.send(request, **kwargs)
  File "C:\Users\leot\AppData\Local\Programs\Python\Python313\Lib\site-packages\requests\adapters.py", line 713, in send
    raise ReadTimeout(e, request=request)
requests.exceptions.ReadTimeout: HTTPConnectionPool(host='192.168.88.43', port=5678): Read timed out. (read timeout=30)
2025-09-17 14:00:05,086 - INFO - User 'leot' querying 'erp': '我要做採購退貨要怎麼做'
2025-09-17 14:00:32,319 - INFO - Webhook call for 'erp' succeeded.
2025-09-17 14:04:58,524 - INFO - User 'leot' querying 'erp': '我要做採購退貨要由誰起?'
2025-09-17 14:05:18,557 - INFO - Webhook call for 'erp' succeeded.
2025-09-17 14:08:17,049 - INFO - User 'leot' querying 'erp': '我要使用MRP計算要如何啟動?'
2025-09-17 14:08:41,717 - INFO - Webhook call for 'erp' succeeded.
2025-09-17 14:09:36,617 - INFO - User 'leot' querying 'erp': '信用額度控管方式?'
2025-09-17 14:09:47,768 - INFO - Webhook call for 'erp' succeeded.
2025-09-17 14:10:28,669 - INFO - User 'leot' querying 'erp': '簽核流程設定方式為何?'
2025-09-17 14:10:58,679 - ERROR - Webhook call for 'erp' failed: HTTPConnectionPool(host='192.168.88.43', port=5678): Read timed out. (read timeout=30)
Traceback (most recent call last):
  File "C:\Users\leot\AppData\Local\Programs\Python\Python313\Lib\site-packages\urllib3\connectionpool.py", line 534, in _make_request
    response = conn.getresponse()
  File "C:\Users\leot\AppData\Local\Programs\Python\Python313\Lib\site-packages\urllib3\connection.py", line 516, in getresponse
    httplib_response = super().getresponse()
  File "C:\Users\leot\AppData\Local\Programs\Python\Python313\Lib\http\client.py", line 1430, in getresponse
    response.begin()
    ~~~~~~~~~~~~~~^^
  File "C:\Users\leot\AppData\Local\Programs\Python\Python313\Lib\http\client.py", line 331, in begin
    version, status, reason = self._read_status()
                              ~~~~~~~~~~~~~~~~~^^
  File "C:\Users\leot\AppData\Local\Programs\Python\Python313\Lib\http\client.py", line 292, in _read_status
    line = str(self.fp.readline(_MAXLINE + 1), "iso-8859-1")
               ~~~~~~~~~~~~~~~~^^^^^^^^^^^^^^
  File "C:\Users\leot\AppData\Local\Programs\Python\Python313\Lib\socket.py", line 719, in readinto
    return self._sock.recv_into(b)
           ~~~~~~~~~~~~~~~~~~~~^^^
TimeoutError: timed out

The above exception was the direct cause of the following exception:

Traceback (most recent call last):
  File "C:\Users\leot\AppData\Local\Programs\Python\Python313\Lib\site-packages\requests\adapters.py", line 667, in send
    resp = conn.urlopen(
        method=request.method,
    ...<9 lines>...
        chunked=chunked,
    )
  File "C:\Users\leot\AppData\Local\Programs\Python\Python313\Lib\site-packages\urllib3\connectionpool.py", line 841, in urlopen
    retries = retries.increment(
        method, url, error=new_e, _pool=self, _stacktrace=sys.exc_info()[2]
    )
  File "C:\Users\leot\AppData\Local\Programs\Python\Python313\Lib\site-packages\urllib3\util\retry.py", line 474, in increment
    raise reraise(type(error), error, _stacktrace)
          ~~~~~~~^^^^^^^^^^^^^^^^^^^^^^^^^^^^^^^^^
  File "C:\Users\leot\AppData\Local\Programs\Python\Python313\Lib\site-packages\urllib3\util\util.py", line 39, in reraise
    raise value
  File "C:\Users\leot\AppData\Local\Programs\Python\Python313\Lib\site-packages\urllib3\connectionpool.py", line 787, in urlopen
    response = self._make_request(
        conn,
    ...<10 lines>...
        **response_kw,
    )
  File "C:\Users\leot\AppData\Local\Programs\Python\Python313\Lib\site-packages\urllib3\connectionpool.py", line 536, in _make_request
    self._raise_timeout(err=e, url=url, timeout_value=read_timeout)
    ~~~~~~~~~~~~~~~~~~~^^^^^^^^^^^^^^^^^^^^^^^^^^^^^^^^^^^^^^^^^^^^
  File "C:\Users\leot\AppData\Local\Programs\Python\Python313\Lib\site-packages\urllib3\connectionpool.py", line 367, in _raise_timeout
    raise ReadTimeoutError(
        self, url, f"Read timed out. (read timeout={timeout_value})"
    ) from err
urllib3.exceptions.ReadTimeoutError: HTTPConnectionPool(host='192.168.88.43', port=5678): Read timed out. (read timeout=30)

During handling of the above exception, another exception occurred:

Traceback (most recent call last):
  File "c:\Users\leot\Desktop\AD_Assistant\main.py", line 210, in perform_assistant_query
    response = requests.post(webhook_url, json=payload, headers={'Content-Type': 'application/json'}, timeout=30)
  File "C:\Users\leot\AppData\Local\Programs\Python\Python313\Lib\site-packages\requests\api.py", line 115, in post
    return request("post", url, data=data, json=json, **kwargs)
  File "C:\Users\leot\AppData\Local\Programs\Python\Python313\Lib\site-packages\requests\api.py", line 59, in request
    return session.request(method=method, url=url, **kwargs)
           ~~~~~~~~~~~~~~~^^^^^^^^^^^^^^^^^^^^^^^^^^^^^^^^^^
  File "C:\Users\leot\AppData\Local\Programs\Python\Python313\Lib\site-packages\requests\sessions.py", line 589, in request
    resp = self.send(prep, **send_kwargs)
  File "C:\Users\leot\AppData\Local\Programs\Python\Python313\Lib\site-packages\requests\sessions.py", line 703, in send
    r = adapter.send(request, **kwargs)
  File "C:\Users\leot\AppData\Local\Programs\Python\Python313\Lib\site-packages\requests\adapters.py", line 713, in send
    raise ReadTimeout(e, request=request)
requests.exceptions.ReadTimeout: HTTPConnectionPool(host='192.168.88.43', port=5678): Read timed out. (read timeout=30)
2025-09-17 14:11:08,134 - INFO - User 'leot' querying 'erp': '簽核流程設定方式為何?'
2025-09-17 14:11:26,672 - INFO - Webhook call for 'erp' succeeded.
2025-09-17 14:54:38,586 - INFO - User 'leot' querying 'erp': '我拿到揀貨單之後要如何作業?'
2025-09-17 14:55:08,619 - ERROR - Webhook call for 'erp' failed: HTTPConnectionPool(host='192.168.88.43', port=5678): Read timed out. (read timeout=30)
Traceback (most recent call last):
  File "C:\Users\leot\AppData\Local\Programs\Python\Python313\Lib\site-packages\urllib3\connectionpool.py", line 534, in _make_request
    response = conn.getresponse()
  File "C:\Users\leot\AppData\Local\Programs\Python\Python313\Lib\site-packages\urllib3\connection.py", line 516, in getresponse
    httplib_response = super().getresponse()
  File "C:\Users\leot\AppData\Local\Programs\Python\Python313\Lib\http\client.py", line 1430, in getresponse
    response.begin()
    ~~~~~~~~~~~~~~^^
  File "C:\Users\leot\AppData\Local\Programs\Python\Python313\Lib\http\client.py", line 331, in begin
    version, status, reason = self._read_status()
                              ~~~~~~~~~~~~~~~~~^^
  File "C:\Users\leot\AppData\Local\Programs\Python\Python313\Lib\http\client.py", line 292, in _read_status
    line = str(self.fp.readline(_MAXLINE + 1), "iso-8859-1")
               ~~~~~~~~~~~~~~~~^^^^^^^^^^^^^^
  File "C:\Users\leot\AppData\Local\Programs\Python\Python313\Lib\socket.py", line 719, in readinto
    return self._sock.recv_into(b)
           ~~~~~~~~~~~~~~~~~~~~^^^
TimeoutError: timed out

The above exception was the direct cause of the following exception:

Traceback (most recent call last):
  File "C:\Users\leot\AppData\Local\Programs\Python\Python313\Lib\site-packages\requests\adapters.py", line 667, in send
    resp = conn.urlopen(
        method=request.method,
    ...<9 lines>...
        chunked=chunked,
    )
  File "C:\Users\leot\AppData\Local\Programs\Python\Python313\Lib\site-packages\urllib3\connectionpool.py", line 841, in urlopen
    retries = retries.increment(
        method, url, error=new_e, _pool=self, _stacktrace=sys.exc_info()[2]
    )
  File "C:\Users\leot\AppData\Local\Programs\Python\Python313\Lib\site-packages\urllib3\util\retry.py", line 474, in increment
    raise reraise(type(error), error, _stacktrace)
          ~~~~~~~^^^^^^^^^^^^^^^^^^^^^^^^^^^^^^^^^
  File "C:\Users\leot\AppData\Local\Programs\Python\Python313\Lib\site-packages\urllib3\util\util.py", line 39, in reraise
    raise value
  File "C:\Users\leot\AppData\Local\Programs\Python\Python313\Lib\site-packages\urllib3\connectionpool.py", line 787, in urlopen
    response = self._make_request(
        conn,
    ...<10 lines>...
        **response_kw,
    )
  File "C:\Users\leot\AppData\Local\Programs\Python\Python313\Lib\site-packages\urllib3\connectionpool.py", line 536, in _make_request
    self._raise_timeout(err=e, url=url, timeout_value=read_timeout)
    ~~~~~~~~~~~~~~~~~~~^^^^^^^^^^^^^^^^^^^^^^^^^^^^^^^^^^^^^^^^^^^^
  File "C:\Users\leot\AppData\Local\Programs\Python\Python313\Lib\site-packages\urllib3\connectionpool.py", line 367, in _raise_timeout
    raise ReadTimeoutError(
        self, url, f"Read timed out. (read timeout={timeout_value})"
    ) from err
urllib3.exceptions.ReadTimeoutError: HTTPConnectionPool(host='192.168.88.43', port=5678): Read timed out. (read timeout=30)

During handling of the above exception, another exception occurred:

Traceback (most recent call last):
  File "c:\Users\leot\Desktop\AD_Assistant\main.py", line 210, in perform_assistant_query
    response = requests.post(webhook_url, json=payload, headers={'Content-Type': 'application/json'}, timeout=30)
  File "C:\Users\leot\AppData\Local\Programs\Python\Python313\Lib\site-packages\requests\api.py", line 115, in post
    return request("post", url, data=data, json=json, **kwargs)
  File "C:\Users\leot\AppData\Local\Programs\Python\Python313\Lib\site-packages\requests\api.py", line 59, in request
    return session.request(method=method, url=url, **kwargs)
           ~~~~~~~~~~~~~~~^^^^^^^^^^^^^^^^^^^^^^^^^^^^^^^^^^
  File "C:\Users\leot\AppData\Local\Programs\Python\Python313\Lib\site-packages\requests\sessions.py", line 589, in request
    resp = self.send(prep, **send_kwargs)
  File "C:\Users\leot\AppData\Local\Programs\Python\Python313\Lib\site-packages\requests\sessions.py", line 703, in send
    r = adapter.send(request, **kwargs)
  File "C:\Users\leot\AppData\Local\Programs\Python\Python313\Lib\site-packages\requests\adapters.py", line 713, in send
    raise ReadTimeout(e, request=request)
requests.exceptions.ReadTimeout: HTTPConnectionPool(host='192.168.88.43', port=5678): Read timed out. (read timeout=30)
2025-09-17 15:02:58,773 - INFO - User 'leot' querying 'erp': '資源及工時表可以一起使用?'
2025-09-17 15:03:28,799 - ERROR - Webhook call for 'erp' failed: HTTPConnectionPool(host='192.168.88.43', port=5678): Read timed out. (read timeout=30)
Traceback (most recent call last):
  File "C:\Users\leot\AppData\Local\Programs\Python\Python313\Lib\site-packages\urllib3\connectionpool.py", line 534, in _make_request
    response = conn.getresponse()
  File "C:\Users\leot\AppData\Local\Programs\Python\Python313\Lib\site-packages\urllib3\connection.py", line 516, in getresponse
    httplib_response = super().getresponse()
  File "C:\Users\leot\AppData\Local\Programs\Python\Python313\Lib\http\client.py", line 1430, in getresponse
    response.begin()
    ~~~~~~~~~~~~~~^^
  File "C:\Users\leot\AppData\Local\Programs\Python\Python313\Lib\http\client.py", line 331, in begin
    version, status, reason = self._read_status()
                              ~~~~~~~~~~~~~~~~~^^
  File "C:\Users\leot\AppData\Local\Programs\Python\Python313\Lib\http\client.py", line 292, in _read_status
    line = str(self.fp.readline(_MAXLINE + 1), "iso-8859-1")
               ~~~~~~~~~~~~~~~~^^^^^^^^^^^^^^
  File "C:\Users\leot\AppData\Local\Programs\Python\Python313\Lib\socket.py", line 719, in readinto
    return self._sock.recv_into(b)
           ~~~~~~~~~~~~~~~~~~~~^^^
TimeoutError: timed out

The above exception was the direct cause of the following exception:

Traceback (most recent call last):
  File "C:\Users\leot\AppData\Local\Programs\Python\Python313\Lib\site-packages\requests\adapters.py", line 667, in send
    resp = conn.urlopen(
        method=request.method,
    ...<9 lines>...
        chunked=chunked,
    )
  File "C:\Users\leot\AppData\Local\Programs\Python\Python313\Lib\site-packages\urllib3\connectionpool.py", line 841, in urlopen
    retries = retries.increment(
        method, url, error=new_e, _pool=self, _stacktrace=sys.exc_info()[2]
    )
  File "C:\Users\leot\AppData\Local\Programs\Python\Python313\Lib\site-packages\urllib3\util\retry.py", line 474, in increment
    raise reraise(type(error), error, _stacktrace)
          ~~~~~~~^^^^^^^^^^^^^^^^^^^^^^^^^^^^^^^^^
  File "C:\Users\leot\AppData\Local\Programs\Python\Python313\Lib\site-packages\urllib3\util\util.py", line 39, in reraise
    raise value
  File "C:\Users\leot\AppData\Local\Programs\Python\Python313\Lib\site-packages\urllib3\connectionpool.py", line 787, in urlopen
    response = self._make_request(
        conn,
    ...<10 lines>...
        **response_kw,
    )
  File "C:\Users\leot\AppData\Local\Programs\Python\Python313\Lib\site-packages\urllib3\connectionpool.py", line 536, in _make_request
    self._raise_timeout(err=e, url=url, timeout_value=read_timeout)
    ~~~~~~~~~~~~~~~~~~~^^^^^^^^^^^^^^^^^^^^^^^^^^^^^^^^^^^^^^^^^^^^
  File "C:\Users\leot\AppData\Local\Programs\Python\Python313\Lib\site-packages\urllib3\connectionpool.py", line 367, in _raise_timeout
    raise ReadTimeoutError(
        self, url, f"Read timed out. (read timeout={timeout_value})"
    ) from err
urllib3.exceptions.ReadTimeoutError: HTTPConnectionPool(host='192.168.88.43', port=5678): Read timed out. (read timeout=30)

During handling of the above exception, another exception occurred:

Traceback (most recent call last):
  File "c:\Users\leot\Desktop\AD_Assistant\main.py", line 210, in perform_assistant_query
    response = requests.post(webhook_url, json=payload, headers={'Content-Type': 'application/json'}, timeout=30)
  File "C:\Users\leot\AppData\Local\Programs\Python\Python313\Lib\site-packages\requests\api.py", line 115, in post
    return request("post", url, data=data, json=json, **kwargs)
  File "C:\Users\leot\AppData\Local\Programs\Python\Python313\Lib\site-packages\requests\api.py", line 59, in request
    return session.request(method=method, url=url, **kwargs)
           ~~~~~~~~~~~~~~~^^^^^^^^^^^^^^^^^^^^^^^^^^^^^^^^^^
  File "C:\Users\leot\AppData\Local\Programs\Python\Python313\Lib\site-packages\requests\sessions.py", line 589, in request
    resp = self.send(prep, **send_kwargs)
  File "C:\Users\leot\AppData\Local\Programs\Python\Python313\Lib\site-packages\requests\sessions.py", line 703, in send
    r = adapter.send(request, **kwargs)
  File "C:\Users\leot\AppData\Local\Programs\Python\Python313\Lib\site-packages\requests\adapters.py", line 713, in send
    raise ReadTimeout(e, request=request)
requests.exceptions.ReadTimeout: HTTPConnectionPool(host='192.168.88.43', port=5678): Read timed out. (read timeout=30)
2025-09-17 15:03:35,535 - INFO - User 'leot' querying 'erp': 'C:/Users/leot/Downloads/SAP B1人力資源.pdf
C:/Users/leot/Downloads/SAP B1生產模組.pdf
C:/Users/leot/Downloads/SAP B1存貨模組part1.pdf
C:/Users/leot/Downloads/SAP B1存貨模組part2.pdf
C:/Users/leot/Downloads/How_to_Work_with_Resources_and_Production_in_SAP_Business_One.pdf'
2025-09-17 15:03:49,342 - INFO - Webhook call for 'erp' succeeded.
2025-09-17 15:03:56,385 - INFO - User 'leot' querying 'erp': '資源及工時表可以一起使用?'
2025-09-17 15:04:22,016 - INFO - Webhook call for 'erp' succeeded.
2025-09-17 15:06:19,299 - INFO - User 'leot' querying 'erp': '工時表的來源可以直接是人力資源使用量?'
2025-09-17 15:06:37,340 - INFO - Webhook call for 'erp' succeeded.
2025-09-17 15:07:20,562 - INFO - User 'leot' querying 'erp': '工時表資料來源為何?'
2025-09-17 15:07:33,828 - INFO - Webhook call for 'erp' succeeded.
2025-09-17 15:08:08,874 - INFO - User 'leot' querying 'erp': '我拿到揀貨單之後要如何作業?'
2025-09-17 15:08:38,255 - INFO - Webhook call for 'erp' succeeded.
2025-09-17 15:12:07,873 - INFO - User 'leot' closed application.
2025-09-17 15:47:31,153 - INFO - ================ Application Started ================
2025-09-17 15:47:39,513 - INFO - User 'leot' is attempting to log in.
2025-09-17 15:47:39,660 - INFO - User 'leot' logged in successfully. Groups: ['LCConfidential', 'LCIT']
2025-09-17 15:47:47,623 - INFO - User 'leot' closed application.
2025-09-17 15:48:12,487 - INFO - ================ Application Started ================
2025-09-17 15:48:18,668 - INFO - User 'leot' is attempting to log in.
2025-09-17 15:48:18,766 - INFO - User 'leot' logged in successfully. Groups: ['LCConfidential', 'LCIT']
2025-09-17 15:49:47,808 - INFO - User 'leot' querying 'erp': '收到揀單怎麼辦?'
2025-09-17 15:50:18,758 - INFO - Received from n8n: {'output': '**收到揀單後的處理流程**\n\n1. **列印揀貨單**  \n   先將系統產生的揀貨單列印出來，方便倉管人員直接使用。  \n   *來源：『撿貨包裝與生產經理操作說明』第\u202f11\u202f頁（紙本揀貨單列印後交給倉管）*\n\n2. **交給倉管進行揀貨**  \n   把列印好的揀貨單交給倉管或揀貨人員，他們根據清單從倉庫挑取商品。  \n   *來源：同上第\u202f11\u202f頁*\n\n3. **揀貨完成後轉成出貨單**  \n   當揀貨人員完成所有商品的挑取後，倉管會將揀貨單的資訊轉成正式的出貨單（Delivery Order），以便後續的物流、發票等流程。  \n   *來源：『庫別儲位建立手冊』第\u202f25\u202f頁（倉管至揀貨清單完成揀貨後，轉成出貨單）*\n\n簡而言之：列印揀貨單 → 交給倉管揀貨 → 揀貨完成後轉成出貨單。'}
2025-09-17 15:50:33,050 - INFO - User 'leot' closed application.
2025-09-17 15:52:40,417 - INFO - ================ Application Started ================
2025-09-17 15:52:48,534 - INFO - User 'leot' is attempting to log in.
2025-09-17 15:52:48,624 - INFO - User 'leot' logged in successfully. Groups: ['LCConfidential', 'LCIT']
2025-09-17 15:53:13,808 - INFO - User 'leot' querying 'erp': '我要怎麼做生產發貨?'
2025-09-17 15:53:30,731 - INFO - Received from n8n: {'output': '**生產發貨（Production Shipment）流程概述**  \n\n1. **開啟「生產發貨」單據**  \n   * 進入「存貨發貨」模組 → 選擇「生產發貨」單據。  \n2. **輸入基本資訊**  \n   * 成品品項、數量、倉庫等。  \n3. **核發手動項目**  \n   * 系統會將手動項目（如人工、工序成本）核發至對應的生產訂單。  \n4. **確認並傳送**  \n   * 輸入完成後，確認資料無誤，傳送至生產訂單。  \n5. **成本過帳**  \n   * *在傳送時*：  \n     * 過帳項目的費用。  \n     * 同日記帳分錄也會過帳資源費用，資源費用會由「資源費用科目」移轉至「相關資源在製品科目」。  \n   * 依資源主檔中「總計標準資源成本」與「進階總帳科目決定規則」計算，實際過帳最多可分為 10 個資源費用科目。  \n6. **完成後檢查**  \n   * 檢查「在製品」帳務是否正確、WIP 科目是否更新。  \n7. **結案**  \n   * 確認完成度後，將單據結案，生產訂單可進入「成品」階段。  \n\n> 以上流程說明來自 SAP B1 的「生產發貨」說明文件（PDF ID：`d83046da-e28e-498f-9a22-8ee651984bd4`）。  \n\n> 若需詳細操作步驟或畫面示意，請參考同一份 PDF 的前後章節。'}
2025-09-17 15:54:08,291 - INFO - User 'leot' closed application.
2025-09-17 15:57:09,468 - INFO - ================ Application Started ================
2025-09-17 15:57:19,572 - INFO - User 'leot' is attempting to log in.
2025-09-17 15:57:19,694 - INFO - User 'leot' logged in successfully. Groups: ['LCConfidential', 'LCIT']
2025-09-17 15:58:08,841 - INFO - User 'leot' querying 'policy': '我上班途中撞車了, 我可以請什麼假或申請什麼補償'
2025-09-17 15:58:31,722 - INFO - Received from n8n: {'output': ''}
2025-09-17 15:58:44,060 - INFO - User 'leot' closed application.
2025-09-17 16:09:25,050 - INFO - ================ Application Started ================
2025-09-17 16:09:32,412 - INFO - User 'leot' is attempting to log in.
2025-09-17 16:09:32,559 - INFO - User 'leot' logged in successfully. Groups: ['LCConfidential', 'LCIT']
2025-09-17 16:13:49,492 - INFO - User 'leot' closed application.
2025-09-17 16:13:52,686 - INFO - ================ Application Started ================
2025-09-17 16:14:13,969 - INFO - ================ Application Started ================
2025-09-17 16:14:19,963 - INFO - User 'leot' is attempting to log in.
2025-09-17 16:14:20,068 - INFO - User 'leot' logged in successfully. Groups: ['LCConfidential', 'LCIT']
2025-09-17 16:14:28,968 - INFO - User 'leot' closed application.
2025-09-17 16:15:12,629 - INFO - ================ Application Started ================
2025-09-17 16:15:18,967 - INFO - User 'leot' is attempting to log in.
2025-09-17 16:15:19,074 - INFO - User 'leot' logged in successfully. Groups: ['LCConfidential', 'LCIT']
2025-09-17 16:15:27,000 - INFO - User 'leot' closed application.
2025-09-17 16:21:57,036 - INFO - ================ Application Started ================
2025-09-17 16:22:03,198 - INFO - User 'leot' is attempting to log in.
2025-09-17 16:22:03,306 - INFO - User 'leot' logged in successfully. Groups: ['LCConfidential', 'LCIT']
2025-09-17 16:22:09,638 - INFO - User 'leot' closed application.
2025-09-17 16:22:22,601 - INFO - ================ Application Started ================
2025-09-17 16:22:28,693 - INFO - User 'leot' is attempting to log in.
2025-09-17 16:22:28,789 - INFO - User 'leot' logged in successfully. Groups: ['LCConfidential', 'LCIT']
2025-09-17 16:23:09,220 - INFO - User 'leot' querying 'policy': '我上班途中被砍了, 我要怎麼假, 有什麼補償?'
2025-09-17 16:27:05,667 - INFO - ================ Application Started ================
2025-09-17 16:27:12,298 - INFO - User 'leot' is attempting to log in.
2025-09-17 16:27:12,431 - INFO - User 'leot' logged in successfully. Groups: ['LCConfidential', 'LCIT']
2025-09-17 16:27:56,091 - INFO - User 'leot' querying 'erp': '採購單要改單價怎麼辦?'
2025-09-17 16:28:21,363 - INFO - Webhook call for 'erp' succeeded.
2025-09-17 16:29:04,318 - INFO - User 'leot' querying 'erp': '採購單要變更怎麼辦?'
2025-09-17 16:29:34,336 - ERROR - Webhook call for 'erp' failed: HTTPConnectionPool(host='192.168.88.43', port=5678): Read timed out. (read timeout=30)
Traceback (most recent call last):
  File "C:\Users\leot\AppData\Local\Programs\Python\Python313\Lib\site-packages\urllib3\connectionpool.py", line 534, in _make_request
    response = conn.getresponse()
  File "C:\Users\leot\AppData\Local\Programs\Python\Python313\Lib\site-packages\urllib3\connection.py", line 516, in getresponse
    httplib_response = super().getresponse()
  File "C:\Users\leot\AppData\Local\Programs\Python\Python313\Lib\http\client.py", line 1430, in getresponse
    response.begin()
    ~~~~~~~~~~~~~~^^
  File "C:\Users\leot\AppData\Local\Programs\Python\Python313\Lib\http\client.py", line 331, in begin
    version, status, reason = self._read_status()
                              ~~~~~~~~~~~~~~~~~^^
  File "C:\Users\leot\AppData\Local\Programs\Python\Python313\Lib\http\client.py", line 292, in _read_status
    line = str(self.fp.readline(_MAXLINE + 1), "iso-8859-1")
               ~~~~~~~~~~~~~~~~^^^^^^^^^^^^^^
  File "C:\Users\leot\AppData\Local\Programs\Python\Python313\Lib\socket.py", line 719, in readinto
    return self._sock.recv_into(b)
           ~~~~~~~~~~~~~~~~~~~~^^^
TimeoutError: timed out

The above exception was the direct cause of the following exception:

Traceback (most recent call last):
  File "C:\Users\leot\AppData\Local\Programs\Python\Python313\Lib\site-packages\requests\adapters.py", line 667, in send
    resp = conn.urlopen(
        method=request.method,
    ...<9 lines>...
        chunked=chunked,
    )
  File "C:\Users\leot\AppData\Local\Programs\Python\Python313\Lib\site-packages\urllib3\connectionpool.py", line 841, in urlopen
    retries = retries.increment(
        method, url, error=new_e, _pool=self, _stacktrace=sys.exc_info()[2]
    )
  File "C:\Users\leot\AppData\Local\Programs\Python\Python313\Lib\site-packages\urllib3\util\retry.py", line 474, in increment
    raise reraise(type(error), error, _stacktrace)
          ~~~~~~~^^^^^^^^^^^^^^^^^^^^^^^^^^^^^^^^^
  File "C:\Users\leot\AppData\Local\Programs\Python\Python313\Lib\site-packages\urllib3\util\util.py", line 39, in reraise
    raise value
  File "C:\Users\leot\AppData\Local\Programs\Python\Python313\Lib\site-packages\urllib3\connectionpool.py", line 787, in urlopen
    response = self._make_request(
        conn,
    ...<10 lines>...
        **response_kw,
    )
  File "C:\Users\leot\AppData\Local\Programs\Python\Python313\Lib\site-packages\urllib3\connectionpool.py", line 536, in _make_request
    self._raise_timeout(err=e, url=url, timeout_value=read_timeout)
    ~~~~~~~~~~~~~~~~~~~^^^^^^^^^^^^^^^^^^^^^^^^^^^^^^^^^^^^^^^^^^^^
  File "C:\Users\leot\AppData\Local\Programs\Python\Python313\Lib\site-packages\urllib3\connectionpool.py", line 367, in _raise_timeout
    raise ReadTimeoutError(
        self, url, f"Read timed out. (read timeout={timeout_value})"
    ) from err
urllib3.exceptions.ReadTimeoutError: HTTPConnectionPool(host='192.168.88.43', port=5678): Read timed out. (read timeout=30)

During handling of the above exception, another exception occurred:

Traceback (most recent call last):
  File "c:\Users\leot\Desktop\AD_Assistant\main.py", line 200, in perform_assistant_query
    response = requests.post(webhook_url, json=payload, headers={'Content-Type': 'application/json'}, timeout=30)
  File "C:\Users\leot\AppData\Local\Programs\Python\Python313\Lib\site-packages\requests\api.py", line 115, in post
    return request("post", url, data=data, json=json, **kwargs)
  File "C:\Users\leot\AppData\Local\Programs\Python\Python313\Lib\site-packages\requests\api.py", line 59, in request
    return session.request(method=method, url=url, **kwargs)
           ~~~~~~~~~~~~~~~^^^^^^^^^^^^^^^^^^^^^^^^^^^^^^^^^^
  File "C:\Users\leot\AppData\Local\Programs\Python\Python313\Lib\site-packages\requests\sessions.py", line 589, in request
    resp = self.send(prep, **send_kwargs)
  File "C:\Users\leot\AppData\Local\Programs\Python\Python313\Lib\site-packages\requests\sessions.py", line 703, in send
    r = adapter.send(request, **kwargs)
  File "C:\Users\leot\AppData\Local\Programs\Python\Python313\Lib\site-packages\requests\adapters.py", line 713, in send
    raise ReadTimeout(e, request=request)
requests.exceptions.ReadTimeout: HTTPConnectionPool(host='192.168.88.43', port=5678): Read timed out. (read timeout=30)
2025-09-17 16:37:29,729 - INFO - User 'leot' querying 'erp': '採購單要變更怎麼辦?'
2025-09-17 16:37:59,223 - INFO - User 'leot' closed application.
2025-09-17 16:38:04,731 - INFO - ================ Application Started ================
2025-09-17 16:38:10,521 - INFO - User 'leot' is attempting to log in.
2025-09-17 16:38:10,641 - INFO - User 'leot' logged in successfully. Groups: ['LCConfidential', 'LCIT']
2025-09-17 16:38:35,477 - INFO - User 'leot' querying 'erp': '採購單要變更要怎麼辦?'
2025-09-17 16:38:59,848 - INFO - Webhook call for 'erp' succeeded.
2025-09-17 16:42:23,130 - INFO - User 'leot' querying 'policy': '採購單要變更要怎麼做?'
2025-09-17 16:42:45,600 - INFO - Webhook call for 'policy' succeeded.
2025-09-17 16:45:14,053 - INFO - User 'leot' querying 'policy': '我上班途中皮砍了, 公司有什麼補償, 可以請假嗎?'
2025-09-17 16:45:43,209 - INFO - Webhook call for 'policy' succeeded.
2025-09-17 16:58:50,186 - INFO - User 'leot' querying 'policy': '我上班途中被砍了, 公司有什麼補償, 可以請假嗎?'
2025-09-17 16:59:13,448 - INFO - Webhook call for 'policy' succeeded.
2025-09-17 17:01:45,311 - INFO - User 'leot' querying 'policy': '我上班途中被砍了, 公司有什麼補償, 可以請假嗎?'
2025-09-17 17:02:12,824 - INFO - Webhook call for 'policy' succeeded.
2025-09-17 17:03:22,396 - INFO - User 'leot' querying 'policy': '那我被砍到死了,有什補助?'
2025-09-17 17:03:43,976 - INFO - Webhook call for 'policy' succeeded.
2025-09-17 17:05:30,937 - INFO - User 'leot' querying 'policy': '那如果我被性騷擾怎麼辦?'
2025-09-17 17:05:44,402 - INFO - Webhook call for 'policy' succeeded.
2025-09-17 17:06:46,138 - INFO - User 'leot' querying 'policy': '如果我是性騷擾其它員工會怎樣?'
2025-09-17 17:07:07,628 - INFO - Webhook call for 'policy' succeeded.
2025-09-17 17:07:40,621 - INFO - User 'leot' querying 'policy': '那我可以申訴嗎?'
2025-09-17 17:07:59,174 - INFO - Webhook call for 'policy' succeeded.
2025-09-17 17:09:15,998 - INFO - User 'leot' closed application.
2025-09-18 08:27:57,134 - INFO - ================ Application Started ================
2025-09-18 08:28:04,241 - INFO - User 'leot' is attempting to log in.
2025-09-18 08:28:04,399 - INFO - User 'leot' logged in successfully. Groups: ['LCConfidential', 'LCIT']
2025-09-18 08:28:28,358 - INFO - User 'leot' closed application.
2025-09-18 08:29:11,065 - INFO - ================ Application Started ================
2025-09-18 08:29:17,693 - INFO - User 'leot' is attempting to log in.
2025-09-18 08:29:17,788 - INFO - User 'leot' logged in successfully. Groups: ['LCConfidential', 'LCIT']
2025-09-18 08:30:03,265 - INFO - User 'leot' closed application.
2025-09-18 11:38:33,965 - INFO - ================ Application Started ================
2025-09-18 11:38:40,848 - INFO - User 'leot' is attempting to log in.
2025-09-18 11:38:40,979 - INFO - User 'leot' logged in successfully. Groups: ['LCConfidential', 'LCIT']
2025-09-18 11:38:58,579 - INFO - User 'leot' querying 'meeting': '' with file: C:/Users/leot/Documents/新人到職設定及安裝.pdf
2025-09-18 11:38:59,045 - ERROR - Webhook call for '會議助理' failed: Expecting value: line 1 column 1 (char 0)
Traceback (most recent call last):
  File "C:\Users\leot\AppData\Local\Programs\Python\Python313\Lib\site-packages\requests\models.py", line 974, in json
    return complexjson.loads(self.text, **kwargs)
           ~~~~~~~~~~~~~~~~~^^^^^^^^^^^^^^^^^^^^^
  File "C:\Users\leot\AppData\Local\Programs\Python\Python313\Lib\json\__init__.py", line 346, in loads
    return _default_decoder.decode(s)
           ~~~~~~~~~~~~~~~~~~~~~~~^^^
  File "C:\Users\leot\AppData\Local\Programs\Python\Python313\Lib\json\decoder.py", line 345, in decode
    obj, end = self.raw_decode(s, idx=_w(s, 0).end())
               ~~~~~~~~~~~~~~~^^^^^^^^^^^^^^^^^^^^^^^
  File "C:\Users\leot\AppData\Local\Programs\Python\Python313\Lib\json\decoder.py", line 363, in raw_decode
    raise JSONDecodeError("Expecting value", s, err.value) from None
json.decoder.JSONDecodeError: Expecting value: line 1 column 1 (char 0)

During handling of the above exception, another exception occurred:

Traceback (most recent call last):
  File "c:\Users\leot\Desktop\AD_Assistant\main.py", line 276, in perform_assistant_query
    response_data = response.json()
  File "C:\Users\leot\AppData\Local\Programs\Python\Python313\Lib\site-packages\requests\models.py", line 978, in json
    raise RequestsJSONDecodeError(e.msg, e.doc, e.pos)
requests.exceptions.JSONDecodeError: Expecting value: line 1 column 1 (char 0)
2025-09-18 13:05:21,774 - INFO - User 'leot' closed application.
2025-09-18 13:05:27,740 - INFO - ================ Application Started ================
2025-09-18 13:05:33,860 - INFO - User 'leot' is attempting to log in.
2025-09-18 13:05:33,964 - INFO - User 'leot' logged in successfully. Groups: ['LCConfidential', 'LCIT']
2025-09-18 13:05:51,631 - INFO - User 'leot' querying 'meeting': '' with file: C:/Users/leot/Documents/20250424回簽.pdf
2025-09-18 13:05:52,200 - ERROR - Webhook call for '會議助理' failed: Expecting value: line 1 column 1 (char 0)
Traceback (most recent call last):
  File "C:\Users\leot\AppData\Local\Programs\Python\Python313\Lib\site-packages\requests\models.py", line 974, in json
    return complexjson.loads(self.text, **kwargs)
           ~~~~~~~~~~~~~~~~~^^^^^^^^^^^^^^^^^^^^^
  File "C:\Users\leot\AppData\Local\Programs\Python\Python313\Lib\json\__init__.py", line 346, in loads
    return _default_decoder.decode(s)
           ~~~~~~~~~~~~~~~~~~~~~~~^^^
  File "C:\Users\leot\AppData\Local\Programs\Python\Python313\Lib\json\decoder.py", line 345, in decode
    obj, end = self.raw_decode(s, idx=_w(s, 0).end())
               ~~~~~~~~~~~~~~~^^^^^^^^^^^^^^^^^^^^^^^
  File "C:\Users\leot\AppData\Local\Programs\Python\Python313\Lib\json\decoder.py", line 363, in raw_decode
    raise JSONDecodeError("Expecting value", s, err.value) from None
json.decoder.JSONDecodeError: Expecting value: line 1 column 1 (char 0)

During handling of the above exception, another exception occurred:

Traceback (most recent call last):
  File "c:\Users\leot\Desktop\AD_Assistant\main.py", line 297, in perform_assistant_query
    response_data = response.json()
  File "C:\Users\leot\AppData\Local\Programs\Python\Python313\Lib\site-packages\requests\models.py", line 978, in json
    raise RequestsJSONDecodeError(e.msg, e.doc, e.pos)
requests.exceptions.JSONDecodeError: Expecting value: line 1 column 1 (char 0)
2025-09-18 13:09:22,093 - INFO - User 'leot' closed application.
2025-09-18 13:09:29,869 - INFO - ================ Application Started ================
2025-09-18 13:09:37,561 - INFO - User 'leot' is attempting to log in.
2025-09-18 13:09:37,663 - INFO - User 'leot' logged in successfully. Groups: ['LCConfidential', 'LCIT']
2025-09-18 13:09:54,364 - INFO - User 'leot' querying 'meeting': '' with file: C:/Users/leot/Documents/資訊需求單-ITR250200014.pdf
2025-09-18 13:09:57,239 - ERROR - Webhook call for '會議助理' failed: Expecting value: line 1 column 1 (char 0)
Traceback (most recent call last):
  File "C:\Users\leot\AppData\Local\Programs\Python\Python313\Lib\site-packages\requests\models.py", line 974, in json
    return complexjson.loads(self.text, **kwargs)
           ~~~~~~~~~~~~~~~~~^^^^^^^^^^^^^^^^^^^^^
  File "C:\Users\leot\AppData\Local\Programs\Python\Python313\Lib\json\__init__.py", line 346, in loads
    return _default_decoder.decode(s)
           ~~~~~~~~~~~~~~~~~~~~~~~^^^
  File "C:\Users\leot\AppData\Local\Programs\Python\Python313\Lib\json\decoder.py", line 345, in decode
    obj, end = self.raw_decode(s, idx=_w(s, 0).end())
               ~~~~~~~~~~~~~~~^^^^^^^^^^^^^^^^^^^^^^^
  File "C:\Users\leot\AppData\Local\Programs\Python\Python313\Lib\json\decoder.py", line 363, in raw_decode
    raise JSONDecodeError("Expecting value", s, err.value) from None
json.decoder.JSONDecodeError: Expecting value: line 1 column 1 (char 0)

During handling of the above exception, another exception occurred:

Traceback (most recent call last):
  File "c:\Users\leot\Desktop\AD_Assistant\main.py", line 298, in perform_assistant_query
    response_data = response.json()
  File "C:\Users\leot\AppData\Local\Programs\Python\Python313\Lib\site-packages\requests\models.py", line 978, in json
    raise RequestsJSONDecodeError(e.msg, e.doc, e.pos)
requests.exceptions.JSONDecodeError: Expecting value: line 1 column 1 (char 0)
2025-09-18 15:43:23,190 - INFO - User 'leot' closed application.
2025-09-18 15:45:35,997 - INFO - ================ Application Started ================
2025-09-18 15:45:47,920 - INFO - User 'leot' is attempting to log in.
2025-09-18 15:45:48,053 - INFO - User 'leot' logged in successfully. Groups: ['LCConfidential', 'LCIT']
2025-09-18 15:46:33,356 - INFO - User 'leot' querying 'meeting': '' with file: C:/Users/leot/Documents/20231024-AR發票.mp4
2025-09-18 15:47:06,604 - ERROR - Webhook call for '會議助理' failed: 'list' object has no attribute 'get'
Traceback (most recent call last):
  File "c:\Users\leot\Desktop\AD_Assistant\main.py", line 299, in perform_assistant_query
    answer = response_data.get("output", "n8n 回應中未找到 'output' 欄位。")
             ^^^^^^^^^^^^^^^^^
AttributeError: 'list' object has no attribute 'get'
2025-09-18 15:51:39,096 - INFO - User 'leot' closed application.
2025-09-18 15:51:46,853 - INFO - ================ Application Started ================
2025-09-18 15:51:52,723 - INFO - User 'leot' is attempting to log in.
2025-09-18 15:51:52,838 - INFO - User 'leot' logged in successfully. Groups: ['LCConfidential', 'LCIT']
2025-09-18 15:52:11,642 - INFO - User 'leot' querying 'meeting': '' with file: C:/Users/leot/Documents/20231024-AR發票.mp4
2025-09-18 15:52:44,964 - ERROR - Webhook call for '會議助理' failed: Expecting value: line 1 column 1 (char 0)
Traceback (most recent call last):
  File "C:\Users\leot\AppData\Local\Programs\Python\Python313\Lib\site-packages\requests\models.py", line 974, in json
    return complexjson.loads(self.text, **kwargs)
           ~~~~~~~~~~~~~~~~~^^^^^^^^^^^^^^^^^^^^^
  File "C:\Users\leot\AppData\Local\Programs\Python\Python313\Lib\json\__init__.py", line 346, in loads
    return _default_decoder.decode(s)
           ~~~~~~~~~~~~~~~~~~~~~~~^^^
  File "C:\Users\leot\AppData\Local\Programs\Python\Python313\Lib\json\decoder.py", line 345, in decode
    obj, end = self.raw_decode(s, idx=_w(s, 0).end())
               ~~~~~~~~~~~~~~~^^^^^^^^^^^^^^^^^^^^^^^
  File "C:\Users\leot\AppData\Local\Programs\Python\Python313\Lib\json\decoder.py", line 363, in raw_decode
    raise JSONDecodeError("Expecting value", s, err.value) from None
json.decoder.JSONDecodeError: Expecting value: line 1 column 1 (char 0)

During handling of the above exception, another exception occurred:

Traceback (most recent call last):
  File "c:\Users\leot\Desktop\AD_Assistant\main.py", line 298, in perform_assistant_query
    response_data = response.json()
  File "C:\Users\leot\AppData\Local\Programs\Python\Python313\Lib\site-packages\requests\models.py", line 978, in json
    raise RequestsJSONDecodeError(e.msg, e.doc, e.pos)
requests.exceptions.JSONDecodeError: Expecting value: line 1 column 1 (char 0)
2025-09-18 16:29:07,685 - INFO - User 'leot' closed application.
2025-09-18 16:29:15,143 - INFO - ================ Application Started ================
2025-09-18 16:29:21,649 - INFO - User 'leot' is attempting to log in.
2025-09-18 16:29:21,750 - INFO - User 'leot' logged in successfully. Groups: ['LCConfidential', 'LCIT']
2025-09-18 16:30:06,674 - INFO - User 'leot' querying 'meeting': '' with file: Z:/共用文件/資訊處/ERP/會議記錄/20230912固資流程會議記錄.pdf
2025-09-18 16:30:20,784 - ERROR - Webhook call for '會議助理' failed: 'list' object has no attribute 'get'
Traceback (most recent call last):
  File "c:\Users\leot\Desktop\AD_Assistant\main.py", line 299, in perform_assistant_query
    answer = response_data.get("output", "n8n 回應中未找到 'output' 欄位。")
             ^^^^^^^^^^^^^^^^^
AttributeError: 'list' object has no attribute 'get'
2025-09-18 16:37:17,985 - INFO - User 'leot' closed application.
2025-09-18 16:37:24,458 - INFO - ================ Application Started ================
2025-09-18 16:37:31,405 - INFO - User 'leot' is attempting to log in.
2025-09-18 16:37:31,511 - INFO - User 'leot' logged in successfully. Groups: ['LCConfidential', 'LCIT']
2025-09-18 16:37:53,147 - INFO - User 'leot' querying 'meeting': '' with file: Z:/共用文件/資訊處/ERP/會議記錄/20230919-固資藍圖驗證第二次.pdf
2025-09-18 16:38:05,854 - ERROR - Webhook call for '會議助理' failed: 'list' object has no attribute 'get'
Traceback (most recent call last):
  File "c:\Users\leot\Desktop\AD_Assistant\main.py", line 299, in perform_assistant_query
    answer = response_data.get("output", "n8n 回應中未找到 'output' 欄位。")
             ^^^^^^^^^^^^^^^^^
AttributeError: 'list' object has no attribute 'get'
2025-09-18 16:48:01,234 - INFO - User 'leot' closed application.
2025-09-18 16:51:22,831 - INFO - ================ Application Started ================
2025-09-18 16:51:29,475 - INFO - User 'leot' is attempting to log in.
2025-09-18 16:51:29,634 - INFO - User 'leot' logged in successfully. Groups: ['LCConfidential', 'LCIT']
2025-09-18 16:51:44,249 - INFO - User 'leot' querying 'meeting': '' with file: Z:/共用文件/資訊處/ERP/會議記錄/20231016生產流程確認會議記錄.pdf
2025-09-18 16:51:51,429 - ERROR - Webhook call for '會議助理' failed: 'list' object has no attribute 'get'
Traceback (most recent call last):
  File "c:\Users\leot\Desktop\AD_Assistant\main.py", line 299, in perform_assistant_query
    answer = response_data.get("output", "n8n 回應中未找到 'output' 欄位。")
             ^^^^^^^^^^^^^^^^^
AttributeError: 'list' object has no attribute 'get'
2025-09-18 16:55:26,926 - INFO - User 'leot' closed application.
2025-09-18 16:55:38,970 - INFO - ================ Application Started ================
2025-09-18 16:55:45,846 - INFO - User 'leot' is attempting to log in.
2025-09-18 16:55:45,940 - INFO - User 'leot' logged in successfully. Groups: ['LCConfidential', 'LCIT']
2025-09-18 16:55:58,747 - INFO - User 'leot' querying 'meeting': '' with file: Z:/共用文件/資訊處/ERP/會議記錄/20231013_採購流程驗証會議_1013.pdf
2025-09-18 16:56:05,499 - INFO - Webhook call for '會議助理' succeeded.
2025-09-18 16:58:44,251 - INFO - User 'leot' closed application.
2025-09-18 16:58:54,594 - INFO - ================ Application Started ================
2025-09-18 16:59:16,206 - INFO - User 'leot' is attempting to log in.
2025-09-18 16:59:16,317 - INFO - User 'leot' logged in successfully. Groups: ['LCConfidential', 'LCIT']
2025-09-18 16:59:40,076 - INFO - User 'leot' querying 'meeting': '' with file: Z:/共用文件/資訊處/ERP/會議記錄/20230831-財務藍圖驗証會議.pdf
2025-09-18 16:59:54,749 - INFO - Webhook call for '會議助理' succeeded.
2025-09-18 17:04:21,899 - INFO - User 'leot' closed application.
2025-09-18 17:06:34,054 - INFO - ================ Application Started ================
2025-09-18 17:06:40,283 - INFO - User 'leot' is attempting to log in.
2025-09-18 17:06:40,394 - INFO - User 'leot' logged in successfully. Groups: ['LCConfidential', 'LCIT']
2025-09-18 17:06:52,349 - INFO - User 'leot' querying 'meeting': '' with file: Z:/共用文件/資訊處/ERP/會議記錄/20230912固資流程會議記錄.pdf
2025-09-18 17:06:59,911 - INFO - Webhook call for '會議助理' succeeded.
2025-09-18 17:07:39,323 - INFO - User 'leot' querying 'meeting': '' with file: C:/Users/leot/Documents/20231024-AR發票.mp4
2025-09-18 17:08:09,927 - ERROR - Webhook call for '會議助理' failed: Expecting value: line 1 column 1 (char 0)
Traceback (most recent call last):
  File "C:\Users\leot\AppData\Local\Programs\Python\Python313\Lib\site-packages\requests\models.py", line 974, in json
    return complexjson.loads(self.text, **kwargs)
           ~~~~~~~~~~~~~~~~~^^^^^^^^^^^^^^^^^^^^^
  File "C:\Users\leot\AppData\Local\Programs\Python\Python313\Lib\json\__init__.py", line 346, in loads
    return _default_decoder.decode(s)
           ~~~~~~~~~~~~~~~~~~~~~~~^^^
  File "C:\Users\leot\AppData\Local\Programs\Python\Python313\Lib\json\decoder.py", line 345, in decode
    obj, end = self.raw_decode(s, idx=_w(s, 0).end())
               ~~~~~~~~~~~~~~~^^^^^^^^^^^^^^^^^^^^^^^
  File "C:\Users\leot\AppData\Local\Programs\Python\Python313\Lib\json\decoder.py", line 363, in raw_decode
    raise JSONDecodeError("Expecting value", s, err.value) from None
json.decoder.JSONDecodeError: Expecting value: line 1 column 1 (char 0)

During handling of the above exception, another exception occurred:

Traceback (most recent call last):
  File "c:\Users\leot\Desktop\AD_Assistant\main.py", line 298, in perform_assistant_query
    response_data = response.json()
  File "C:\Users\leot\AppData\Local\Programs\Python\Python313\Lib\site-packages\requests\models.py", line 978, in json
    raise RequestsJSONDecodeError(e.msg, e.doc, e.pos)
requests.exceptions.JSONDecodeError: Expecting value: line 1 column 1 (char 0)
2025-09-19 08:26:18,204 - INFO - ================ Application Started ================
2025-09-19 08:26:29,900 - INFO - User 'leot' is attempting to log in.
2025-09-19 08:26:30,025 - INFO - User 'leot' logged in successfully. Groups: ['LCConfidential', 'LCIT']
2025-09-19 08:26:47,400 - INFO - User 'leot' querying 'meeting': '' with file: C:/Users/leot/Documents/20231024-AR發票.mp4
2025-09-19 08:27:19,167 - ERROR - Webhook call for '會議助理' failed: Expecting value: line 1 column 1 (char 0)
Traceback (most recent call last):
  File "C:\Users\leot\AppData\Local\Programs\Python\Python313\Lib\site-packages\requests\models.py", line 974, in json
    return complexjson.loads(self.text, **kwargs)
           ~~~~~~~~~~~~~~~~~^^^^^^^^^^^^^^^^^^^^^
  File "C:\Users\leot\AppData\Local\Programs\Python\Python313\Lib\json\__init__.py", line 346, in loads
    return _default_decoder.decode(s)
           ~~~~~~~~~~~~~~~~~~~~~~~^^^
  File "C:\Users\leot\AppData\Local\Programs\Python\Python313\Lib\json\decoder.py", line 345, in decode
    obj, end = self.raw_decode(s, idx=_w(s, 0).end())
               ~~~~~~~~~~~~~~~^^^^^^^^^^^^^^^^^^^^^^^
  File "C:\Users\leot\AppData\Local\Programs\Python\Python313\Lib\json\decoder.py", line 363, in raw_decode
    raise JSONDecodeError("Expecting value", s, err.value) from None
json.decoder.JSONDecodeError: Expecting value: line 1 column 1 (char 0)

During handling of the above exception, another exception occurred:

Traceback (most recent call last):
  File "c:\Users\leot\Desktop\AD_Assistant\main.py", line 298, in perform_assistant_query
    response_data = response.json()
  File "C:\Users\leot\AppData\Local\Programs\Python\Python313\Lib\site-packages\requests\models.py", line 978, in json
    raise RequestsJSONDecodeError(e.msg, e.doc, e.pos)
requests.exceptions.JSONDecodeError: Expecting value: line 1 column 1 (char 0)
2025-09-19 09:03:05,996 - INFO - User 'leot' querying 'meeting': '' with file: C:/Users/leot/Documents/20231024-AR發票.mp4
2025-09-19 09:03:36,384 - ERROR - Webhook call for '會議助理' failed: Expecting value: line 1 column 1 (char 0)
Traceback (most recent call last):
  File "C:\Users\leot\AppData\Local\Programs\Python\Python313\Lib\site-packages\requests\models.py", line 974, in json
    return complexjson.loads(self.text, **kwargs)
           ~~~~~~~~~~~~~~~~~^^^^^^^^^^^^^^^^^^^^^
  File "C:\Users\leot\AppData\Local\Programs\Python\Python313\Lib\json\__init__.py", line 346, in loads
    return _default_decoder.decode(s)
           ~~~~~~~~~~~~~~~~~~~~~~~^^^
  File "C:\Users\leot\AppData\Local\Programs\Python\Python313\Lib\json\decoder.py", line 345, in decode
    obj, end = self.raw_decode(s, idx=_w(s, 0).end())
               ~~~~~~~~~~~~~~~^^^^^^^^^^^^^^^^^^^^^^^
  File "C:\Users\leot\AppData\Local\Programs\Python\Python313\Lib\json\decoder.py", line 363, in raw_decode
    raise JSONDecodeError("Expecting value", s, err.value) from None
json.decoder.JSONDecodeError: Expecting value: line 1 column 1 (char 0)

During handling of the above exception, another exception occurred:

Traceback (most recent call last):
  File "c:\Users\leot\Desktop\AD_Assistant\main.py", line 298, in perform_assistant_query
    response_data = response.json()
  File "C:\Users\leot\AppData\Local\Programs\Python\Python313\Lib\site-packages\requests\models.py", line 978, in json
    raise RequestsJSONDecodeError(e.msg, e.doc, e.pos)
requests.exceptions.JSONDecodeError: Expecting value: line 1 column 1 (char 0)
2025-09-19 09:08:40,858 - INFO - User 'leot' querying 'meeting': '' with file: C:/Users/leot/Documents/20231024-AR發票.mp4
2025-09-19 09:09:40,906 - ERROR - Webhook call for '會議助理' failed: Expecting value: line 1 column 1 (char 0)
Traceback (most recent call last):
  File "C:\Users\leot\AppData\Local\Programs\Python\Python313\Lib\site-packages\requests\models.py", line 974, in json
    return complexjson.loads(self.text, **kwargs)
           ~~~~~~~~~~~~~~~~~^^^^^^^^^^^^^^^^^^^^^
  File "C:\Users\leot\AppData\Local\Programs\Python\Python313\Lib\json\__init__.py", line 346, in loads
    return _default_decoder.decode(s)
           ~~~~~~~~~~~~~~~~~~~~~~~^^^
  File "C:\Users\leot\AppData\Local\Programs\Python\Python313\Lib\json\decoder.py", line 345, in decode
    obj, end = self.raw_decode(s, idx=_w(s, 0).end())
               ~~~~~~~~~~~~~~~^^^^^^^^^^^^^^^^^^^^^^^
  File "C:\Users\leot\AppData\Local\Programs\Python\Python313\Lib\json\decoder.py", line 363, in raw_decode
    raise JSONDecodeError("Expecting value", s, err.value) from None
json.decoder.JSONDecodeError: Expecting value: line 1 column 1 (char 0)

During handling of the above exception, another exception occurred:

Traceback (most recent call last):
  File "c:\Users\leot\Desktop\AD_Assistant\main.py", line 298, in perform_assistant_query
    response_data = response.json()
  File "C:\Users\leot\AppData\Local\Programs\Python\Python313\Lib\site-packages\requests\models.py", line 978, in json
    raise RequestsJSONDecodeError(e.msg, e.doc, e.pos)
requests.exceptions.JSONDecodeError: Expecting value: line 1 column 1 (char 0)
2025-09-19 09:16:23,494 - INFO - User 'leot' querying 'erp': '為何銷售訂單產生撿貨清單會直接變成己核發' with file: None
2025-09-19 09:16:23,537 - ERROR - Webhook call for 'ERP助理' failed: 404 Client Error: Not Found for url: http://192.168.88.43:5678/webhook/ERPAgentWithFile
Traceback (most recent call last):
  File "c:\Users\leot\Desktop\AD_Assistant\main.py", line 297, in perform_assistant_query
    response.raise_for_status()
    ~~~~~~~~~~~~~~~~~~~~~~~~~^^
  File "C:\Users\leot\AppData\Local\Programs\Python\Python313\Lib\site-packages\requests\models.py", line 1024, in raise_for_status
    raise HTTPError(http_error_msg, response=self)
requests.exceptions.HTTPError: 404 Client Error: Not Found for url: http://192.168.88.43:5678/webhook/ERPAgentWithFile
2025-09-19 09:19:52,256 - INFO - User 'leot' querying 'erp': '為何銷售訂單產生撿貨清單會直接變成己核發' with file: None
2025-09-19 09:20:32,265 - ERROR - Webhook call for 'ERP助理' failed: HTTPConnectionPool(host='192.168.88.43', port=5678): Read timed out. (read timeout=40)
Traceback (most recent call last):
  File "C:\Users\leot\AppData\Local\Programs\Python\Python313\Lib\site-packages\urllib3\connectionpool.py", line 534, in _make_request
    response = conn.getresponse()
  File "C:\Users\leot\AppData\Local\Programs\Python\Python313\Lib\site-packages\urllib3\connection.py", line 516, in getresponse
    httplib_response = super().getresponse()
  File "C:\Users\leot\AppData\Local\Programs\Python\Python313\Lib\http\client.py", line 1430, in getresponse
    response.begin()
    ~~~~~~~~~~~~~~^^
  File "C:\Users\leot\AppData\Local\Programs\Python\Python313\Lib\http\client.py", line 331, in begin
    version, status, reason = self._read_status()
                              ~~~~~~~~~~~~~~~~~^^
  File "C:\Users\leot\AppData\Local\Programs\Python\Python313\Lib\http\client.py", line 292, in _read_status
    line = str(self.fp.readline(_MAXLINE + 1), "iso-8859-1")
               ~~~~~~~~~~~~~~~~^^^^^^^^^^^^^^
  File "C:\Users\leot\AppData\Local\Programs\Python\Python313\Lib\socket.py", line 719, in readinto
    return self._sock.recv_into(b)
           ~~~~~~~~~~~~~~~~~~~~^^^
TimeoutError: timed out

The above exception was the direct cause of the following exception:

Traceback (most recent call last):
  File "C:\Users\leot\AppData\Local\Programs\Python\Python313\Lib\site-packages\requests\adapters.py", line 667, in send
    resp = conn.urlopen(
        method=request.method,
    ...<9 lines>...
        chunked=chunked,
    )
  File "C:\Users\leot\AppData\Local\Programs\Python\Python313\Lib\site-packages\urllib3\connectionpool.py", line 841, in urlopen
    retries = retries.increment(
        method, url, error=new_e, _pool=self, _stacktrace=sys.exc_info()[2]
    )
  File "C:\Users\leot\AppData\Local\Programs\Python\Python313\Lib\site-packages\urllib3\util\retry.py", line 474, in increment
    raise reraise(type(error), error, _stacktrace)
          ~~~~~~~^^^^^^^^^^^^^^^^^^^^^^^^^^^^^^^^^
  File "C:\Users\leot\AppData\Local\Programs\Python\Python313\Lib\site-packages\urllib3\util\util.py", line 39, in reraise
    raise value
  File "C:\Users\leot\AppData\Local\Programs\Python\Python313\Lib\site-packages\urllib3\connectionpool.py", line 787, in urlopen
    response = self._make_request(
        conn,
    ...<10 lines>...
        **response_kw,
    )
  File "C:\Users\leot\AppData\Local\Programs\Python\Python313\Lib\site-packages\urllib3\connectionpool.py", line 536, in _make_request
    self._raise_timeout(err=e, url=url, timeout_value=read_timeout)
    ~~~~~~~~~~~~~~~~~~~^^^^^^^^^^^^^^^^^^^^^^^^^^^^^^^^^^^^^^^^^^^^
  File "C:\Users\leot\AppData\Local\Programs\Python\Python313\Lib\site-packages\urllib3\connectionpool.py", line 367, in _raise_timeout
    raise ReadTimeoutError(
        self, url, f"Read timed out. (read timeout={timeout_value})"
    ) from err
urllib3.exceptions.ReadTimeoutError: HTTPConnectionPool(host='192.168.88.43', port=5678): Read timed out. (read timeout=40)

During handling of the above exception, another exception occurred:

Traceback (most recent call last):
  File "c:\Users\leot\Desktop\AD_Assistant\main.py", line 292, in perform_assistant_query
    response = requests.post(webhook_url, json=payload, headers=headers, timeout=40)
  File "C:\Users\leot\AppData\Local\Programs\Python\Python313\Lib\site-packages\requests\api.py", line 115, in post
    return request("post", url, data=data, json=json, **kwargs)
  File "C:\Users\leot\AppData\Local\Programs\Python\Python313\Lib\site-packages\requests\api.py", line 59, in request
    return session.request(method=method, url=url, **kwargs)
           ~~~~~~~~~~~~~~~^^^^^^^^^^^^^^^^^^^^^^^^^^^^^^^^^^
  File "C:\Users\leot\AppData\Local\Programs\Python\Python313\Lib\site-packages\requests\sessions.py", line 589, in request
    resp = self.send(prep, **send_kwargs)
  File "C:\Users\leot\AppData\Local\Programs\Python\Python313\Lib\site-packages\requests\sessions.py", line 703, in send
    r = adapter.send(request, **kwargs)
  File "C:\Users\leot\AppData\Local\Programs\Python\Python313\Lib\site-packages\requests\adapters.py", line 713, in send
    raise ReadTimeout(e, request=request)
requests.exceptions.ReadTimeout: HTTPConnectionPool(host='192.168.88.43', port=5678): Read timed out. (read timeout=40)
2025-09-19 09:25:24,891 - INFO - User 'leot' querying 'erp': '為何銷售訂單產生撿貨清單會直接變成己核發' with file: None
2025-09-19 09:25:47,262 - INFO - Webhook call for 'ERP助理' succeeded.
2025-09-19 09:27:51,787 - INFO - User 'leot' querying 'erp': '但是否是設定原因造成銷售訂單轉揀貨單時變成自動核發' with file: None
2025-09-19 09:28:11,233 - INFO - Webhook call for 'ERP助理' succeeded.
2025-09-19 09:29:52,337 - INFO - User 'leot' querying 'erp': '自動發貨AUTO-ISSUE設定在哪?' with file: None
2025-09-19 09:30:32,357 - ERROR - Webhook call for 'ERP助理' failed: HTTPConnectionPool(host='192.168.88.43', port=5678): Read timed out. (read timeout=40)
Traceback (most recent call last):
  File "C:\Users\leot\AppData\Local\Programs\Python\Python313\Lib\site-packages\urllib3\connectionpool.py", line 534, in _make_request
    response = conn.getresponse()
  File "C:\Users\leot\AppData\Local\Programs\Python\Python313\Lib\site-packages\urllib3\connection.py", line 516, in getresponse
    httplib_response = super().getresponse()
  File "C:\Users\leot\AppData\Local\Programs\Python\Python313\Lib\http\client.py", line 1430, in getresponse
    response.begin()
    ~~~~~~~~~~~~~~^^
  File "C:\Users\leot\AppData\Local\Programs\Python\Python313\Lib\http\client.py", line 331, in begin
    version, status, reason = self._read_status()
                              ~~~~~~~~~~~~~~~~~^^
  File "C:\Users\leot\AppData\Local\Programs\Python\Python313\Lib\http\client.py", line 292, in _read_status
    line = str(self.fp.readline(_MAXLINE + 1), "iso-8859-1")
               ~~~~~~~~~~~~~~~~^^^^^^^^^^^^^^
  File "C:\Users\leot\AppData\Local\Programs\Python\Python313\Lib\socket.py", line 719, in readinto
    return self._sock.recv_into(b)
           ~~~~~~~~~~~~~~~~~~~~^^^
TimeoutError: timed out

The above exception was the direct cause of the following exception:

Traceback (most recent call last):
  File "C:\Users\leot\AppData\Local\Programs\Python\Python313\Lib\site-packages\requests\adapters.py", line 667, in send
    resp = conn.urlopen(
        method=request.method,
    ...<9 lines>...
        chunked=chunked,
    )
  File "C:\Users\leot\AppData\Local\Programs\Python\Python313\Lib\site-packages\urllib3\connectionpool.py", line 841, in urlopen
    retries = retries.increment(
        method, url, error=new_e, _pool=self, _stacktrace=sys.exc_info()[2]
    )
  File "C:\Users\leot\AppData\Local\Programs\Python\Python313\Lib\site-packages\urllib3\util\retry.py", line 474, in increment
    raise reraise(type(error), error, _stacktrace)
          ~~~~~~~^^^^^^^^^^^^^^^^^^^^^^^^^^^^^^^^^
  File "C:\Users\leot\AppData\Local\Programs\Python\Python313\Lib\site-packages\urllib3\util\util.py", line 39, in reraise
    raise value
  File "C:\Users\leot\AppData\Local\Programs\Python\Python313\Lib\site-packages\urllib3\connectionpool.py", line 787, in urlopen
    response = self._make_request(
        conn,
    ...<10 lines>...
        **response_kw,
    )
  File "C:\Users\leot\AppData\Local\Programs\Python\Python313\Lib\site-packages\urllib3\connectionpool.py", line 536, in _make_request
    self._raise_timeout(err=e, url=url, timeout_value=read_timeout)
    ~~~~~~~~~~~~~~~~~~~^^^^^^^^^^^^^^^^^^^^^^^^^^^^^^^^^^^^^^^^^^^^
  File "C:\Users\leot\AppData\Local\Programs\Python\Python313\Lib\site-packages\urllib3\connectionpool.py", line 367, in _raise_timeout
    raise ReadTimeoutError(
        self, url, f"Read timed out. (read timeout={timeout_value})"
    ) from err
urllib3.exceptions.ReadTimeoutError: HTTPConnectionPool(host='192.168.88.43', port=5678): Read timed out. (read timeout=40)

During handling of the above exception, another exception occurred:

Traceback (most recent call last):
  File "c:\Users\leot\Desktop\AD_Assistant\main.py", line 292, in perform_assistant_query
    response = requests.post(webhook_url, json=payload, headers=headers, timeout=40)
  File "C:\Users\leot\AppData\Local\Programs\Python\Python313\Lib\site-packages\requests\api.py", line 115, in post
    return request("post", url, data=data, json=json, **kwargs)
  File "C:\Users\leot\AppData\Local\Programs\Python\Python313\Lib\site-packages\requests\api.py", line 59, in request
    return session.request(method=method, url=url, **kwargs)
           ~~~~~~~~~~~~~~~^^^^^^^^^^^^^^^^^^^^^^^^^^^^^^^^^^
  File "C:\Users\leot\AppData\Local\Programs\Python\Python313\Lib\site-packages\requests\sessions.py", line 589, in request
    resp = self.send(prep, **send_kwargs)
  File "C:\Users\leot\AppData\Local\Programs\Python\Python313\Lib\site-packages\requests\sessions.py", line 703, in send
    r = adapter.send(request, **kwargs)
  File "C:\Users\leot\AppData\Local\Programs\Python\Python313\Lib\site-packages\requests\adapters.py", line 713, in send
    raise ReadTimeout(e, request=request)
requests.exceptions.ReadTimeout: HTTPConnectionPool(host='192.168.88.43', port=5678): Read timed out. (read timeout=40)
2025-09-19 09:37:13,557 - INFO - User 'leot' querying 'erp': '自動發貨AUTO-ISSUE設定在哪?' with file: None
2025-09-19 09:37:53,570 - ERROR - Webhook call for 'ERP助理' failed: HTTPConnectionPool(host='192.168.88.43', port=5678): Read timed out. (read timeout=40)
Traceback (most recent call last):
  File "C:\Users\leot\AppData\Local\Programs\Python\Python313\Lib\site-packages\urllib3\connectionpool.py", line 534, in _make_request
    response = conn.getresponse()
  File "C:\Users\leot\AppData\Local\Programs\Python\Python313\Lib\site-packages\urllib3\connection.py", line 516, in getresponse
    httplib_response = super().getresponse()
  File "C:\Users\leot\AppData\Local\Programs\Python\Python313\Lib\http\client.py", line 1430, in getresponse
    response.begin()
    ~~~~~~~~~~~~~~^^
  File "C:\Users\leot\AppData\Local\Programs\Python\Python313\Lib\http\client.py", line 331, in begin
    version, status, reason = self._read_status()
                              ~~~~~~~~~~~~~~~~~^^
  File "C:\Users\leot\AppData\Local\Programs\Python\Python313\Lib\http\client.py", line 292, in _read_status
    line = str(self.fp.readline(_MAXLINE + 1), "iso-8859-1")
               ~~~~~~~~~~~~~~~~^^^^^^^^^^^^^^
  File "C:\Users\leot\AppData\Local\Programs\Python\Python313\Lib\socket.py", line 719, in readinto
    return self._sock.recv_into(b)
           ~~~~~~~~~~~~~~~~~~~~^^^
TimeoutError: timed out

The above exception was the direct cause of the following exception:

Traceback (most recent call last):
  File "C:\Users\leot\AppData\Local\Programs\Python\Python313\Lib\site-packages\requests\adapters.py", line 667, in send
    resp = conn.urlopen(
        method=request.method,
    ...<9 lines>...
        chunked=chunked,
    )
  File "C:\Users\leot\AppData\Local\Programs\Python\Python313\Lib\site-packages\urllib3\connectionpool.py", line 841, in urlopen
    retries = retries.increment(
        method, url, error=new_e, _pool=self, _stacktrace=sys.exc_info()[2]
    )
  File "C:\Users\leot\AppData\Local\Programs\Python\Python313\Lib\site-packages\urllib3\util\retry.py", line 474, in increment
    raise reraise(type(error), error, _stacktrace)
          ~~~~~~~^^^^^^^^^^^^^^^^^^^^^^^^^^^^^^^^^
  File "C:\Users\leot\AppData\Local\Programs\Python\Python313\Lib\site-packages\urllib3\util\util.py", line 39, in reraise
    raise value
  File "C:\Users\leot\AppData\Local\Programs\Python\Python313\Lib\site-packages\urllib3\connectionpool.py", line 787, in urlopen
    response = self._make_request(
        conn,
    ...<10 lines>...
        **response_kw,
    )
  File "C:\Users\leot\AppData\Local\Programs\Python\Python313\Lib\site-packages\urllib3\connectionpool.py", line 536, in _make_request
    self._raise_timeout(err=e, url=url, timeout_value=read_timeout)
    ~~~~~~~~~~~~~~~~~~~^^^^^^^^^^^^^^^^^^^^^^^^^^^^^^^^^^^^^^^^^^^^
  File "C:\Users\leot\AppData\Local\Programs\Python\Python313\Lib\site-packages\urllib3\connectionpool.py", line 367, in _raise_timeout
    raise ReadTimeoutError(
        self, url, f"Read timed out. (read timeout={timeout_value})"
    ) from err
urllib3.exceptions.ReadTimeoutError: HTTPConnectionPool(host='192.168.88.43', port=5678): Read timed out. (read timeout=40)

During handling of the above exception, another exception occurred:

Traceback (most recent call last):
  File "c:\Users\leot\Desktop\AD_Assistant\main.py", line 292, in perform_assistant_query
    response = requests.post(webhook_url, json=payload, headers=headers, timeout=50)
  File "C:\Users\leot\AppData\Local\Programs\Python\Python313\Lib\site-packages\requests\api.py", line 115, in post
    return request("post", url, data=data, json=json, **kwargs)
  File "C:\Users\leot\AppData\Local\Programs\Python\Python313\Lib\site-packages\requests\api.py", line 59, in request
    return session.request(method=method, url=url, **kwargs)
           ~~~~~~~~~~~~~~~^^^^^^^^^^^^^^^^^^^^^^^^^^^^^^^^^^
  File "C:\Users\leot\AppData\Local\Programs\Python\Python313\Lib\site-packages\requests\sessions.py", line 589, in request
    resp = self.send(prep, **send_kwargs)
  File "C:\Users\leot\AppData\Local\Programs\Python\Python313\Lib\site-packages\requests\sessions.py", line 703, in send
    r = adapter.send(request, **kwargs)
  File "C:\Users\leot\AppData\Local\Programs\Python\Python313\Lib\site-packages\requests\adapters.py", line 713, in send
    raise ReadTimeout(e, request=request)
requests.exceptions.ReadTimeout: HTTPConnectionPool(host='192.168.88.43', port=5678): Read timed out. (read timeout=40)
2025-09-19 09:38:34,661 - INFO - User 'leot' closed application.
2025-09-19 09:38:37,869 - INFO - ================ Application Started ================
2025-09-19 09:38:54,318 - INFO - ================ Application Started ================
2025-09-19 09:39:00,645 - INFO - User 'leot' is attempting to log in.
2025-09-19 09:39:00,780 - INFO - User 'leot' logged in successfully. Groups: ['LCConfidential', 'LCIT']
2025-09-19 09:39:05,213 - INFO - User 'leot' querying 'erp': '自動發貨AUTO-ISSUE設定在哪?' with file: None
2025-09-19 09:39:55,268 - ERROR - Webhook call for 'ERP助理' failed: HTTPConnectionPool(host='192.168.88.43', port=5678): Read timed out. (read timeout=50)
Traceback (most recent call last):
  File "C:\Users\leot\AppData\Local\Programs\Python\Python313\Lib\site-packages\urllib3\connectionpool.py", line 534, in _make_request
    response = conn.getresponse()
  File "C:\Users\leot\AppData\Local\Programs\Python\Python313\Lib\site-packages\urllib3\connection.py", line 516, in getresponse
    httplib_response = super().getresponse()
  File "C:\Users\leot\AppData\Local\Programs\Python\Python313\Lib\http\client.py", line 1430, in getresponse
    response.begin()
    ~~~~~~~~~~~~~~^^
  File "C:\Users\leot\AppData\Local\Programs\Python\Python313\Lib\http\client.py", line 331, in begin
    version, status, reason = self._read_status()
                              ~~~~~~~~~~~~~~~~~^^
  File "C:\Users\leot\AppData\Local\Programs\Python\Python313\Lib\http\client.py", line 292, in _read_status
    line = str(self.fp.readline(_MAXLINE + 1), "iso-8859-1")
               ~~~~~~~~~~~~~~~~^^^^^^^^^^^^^^
  File "C:\Users\leot\AppData\Local\Programs\Python\Python313\Lib\socket.py", line 719, in readinto
    return self._sock.recv_into(b)
           ~~~~~~~~~~~~~~~~~~~~^^^
TimeoutError: timed out

The above exception was the direct cause of the following exception:

Traceback (most recent call last):
  File "C:\Users\leot\AppData\Local\Programs\Python\Python313\Lib\site-packages\requests\adapters.py", line 667, in send
    resp = conn.urlopen(
        method=request.method,
    ...<9 lines>...
        chunked=chunked,
    )
  File "C:\Users\leot\AppData\Local\Programs\Python\Python313\Lib\site-packages\urllib3\connectionpool.py", line 841, in urlopen
    retries = retries.increment(
        method, url, error=new_e, _pool=self, _stacktrace=sys.exc_info()[2]
    )
  File "C:\Users\leot\AppData\Local\Programs\Python\Python313\Lib\site-packages\urllib3\util\retry.py", line 474, in increment
    raise reraise(type(error), error, _stacktrace)
          ~~~~~~~^^^^^^^^^^^^^^^^^^^^^^^^^^^^^^^^^
  File "C:\Users\leot\AppData\Local\Programs\Python\Python313\Lib\site-packages\urllib3\util\util.py", line 39, in reraise
    raise value
  File "C:\Users\leot\AppData\Local\Programs\Python\Python313\Lib\site-packages\urllib3\connectionpool.py", line 787, in urlopen
    response = self._make_request(
        conn,
    ...<10 lines>...
        **response_kw,
    )
  File "C:\Users\leot\AppData\Local\Programs\Python\Python313\Lib\site-packages\urllib3\connectionpool.py", line 536, in _make_request
    self._raise_timeout(err=e, url=url, timeout_value=read_timeout)
    ~~~~~~~~~~~~~~~~~~~^^^^^^^^^^^^^^^^^^^^^^^^^^^^^^^^^^^^^^^^^^^^
  File "C:\Users\leot\AppData\Local\Programs\Python\Python313\Lib\site-packages\urllib3\connectionpool.py", line 367, in _raise_timeout
    raise ReadTimeoutError(
        self, url, f"Read timed out. (read timeout={timeout_value})"
    ) from err
urllib3.exceptions.ReadTimeoutError: HTTPConnectionPool(host='192.168.88.43', port=5678): Read timed out. (read timeout=50)

During handling of the above exception, another exception occurred:

Traceback (most recent call last):
  File "c:\Users\leot\Desktop\AD_Assistant\main.py", line 292, in perform_assistant_query
    response = requests.post(webhook_url, json=payload, headers=headers, timeout=50)
  File "C:\Users\leot\AppData\Local\Programs\Python\Python313\Lib\site-packages\requests\api.py", line 115, in post
    return request("post", url, data=data, json=json, **kwargs)
  File "C:\Users\leot\AppData\Local\Programs\Python\Python313\Lib\site-packages\requests\api.py", line 59, in request
    return session.request(method=method, url=url, **kwargs)
           ~~~~~~~~~~~~~~~^^^^^^^^^^^^^^^^^^^^^^^^^^^^^^^^^^
  File "C:\Users\leot\AppData\Local\Programs\Python\Python313\Lib\site-packages\requests\sessions.py", line 589, in request
    resp = self.send(prep, **send_kwargs)
  File "C:\Users\leot\AppData\Local\Programs\Python\Python313\Lib\site-packages\requests\sessions.py", line 703, in send
    r = adapter.send(request, **kwargs)
  File "C:\Users\leot\AppData\Local\Programs\Python\Python313\Lib\site-packages\requests\adapters.py", line 713, in send
    raise ReadTimeout(e, request=request)
requests.exceptions.ReadTimeout: HTTPConnectionPool(host='192.168.88.43', port=5678): Read timed out. (read timeout=50)
2025-09-19 09:49:19,485 - INFO - User 'leot' closed application.
2025-09-19 09:49:22,073 - INFO - ================ Application Started ================
2025-09-19 09:49:32,331 - INFO - User 'leot' is attempting to log in.
2025-09-19 09:49:32,447 - INFO - User 'leot' logged in successfully. Groups: ['LCConfidential', 'LCIT']
2025-09-19 09:50:00,075 - INFO - User 'leot' querying 'erp': '如何設定自動發貨?' with file: None
2025-09-19 09:50:02,374 - ERROR - Webhook call for 'ERP助理' failed: Expecting value: line 1 column 1 (char 0)
Traceback (most recent call last):
  File "C:\Users\leot\AppData\Local\Programs\Python\Python313\Lib\site-packages\requests\models.py", line 974, in json
    return complexjson.loads(self.text, **kwargs)
           ~~~~~~~~~~~~~~~~~^^^^^^^^^^^^^^^^^^^^^
  File "C:\Users\leot\AppData\Local\Programs\Python\Python313\Lib\json\__init__.py", line 346, in loads
    return _default_decoder.decode(s)
           ~~~~~~~~~~~~~~~~~~~~~~~^^^
  File "C:\Users\leot\AppData\Local\Programs\Python\Python313\Lib\json\decoder.py", line 345, in decode
    obj, end = self.raw_decode(s, idx=_w(s, 0).end())
               ~~~~~~~~~~~~~~~^^^^^^^^^^^^^^^^^^^^^^^
  File "C:\Users\leot\AppData\Local\Programs\Python\Python313\Lib\json\decoder.py", line 363, in raw_decode
    raise JSONDecodeError("Expecting value", s, err.value) from None
json.decoder.JSONDecodeError: Expecting value: line 1 column 1 (char 0)

During handling of the above exception, another exception occurred:

Traceback (most recent call last):
  File "c:\Users\leot\Desktop\AD_Assistant\main.py", line 328, in perform_assistant_query
    response_data = response.json()
  File "C:\Users\leot\AppData\Local\Programs\Python\Python313\Lib\site-packages\requests\models.py", line 978, in json
    raise RequestsJSONDecodeError(e.msg, e.doc, e.pos)
requests.exceptions.JSONDecodeError: Expecting value: line 1 column 1 (char 0)
2025-09-19 09:52:43,030 - INFO - User 'leot' querying 'erp': '如何設定自動發貨?' with file: None
2025-09-19 09:53:22,774 - INFO - Webhook call for 'ERP助理' succeeded.
2025-09-19 09:54:27,519 - INFO - User 'leot' querying 'erp': '為何某些倉庫會自動貨?' with file: None
2025-09-19 09:54:53,710 - INFO - Webhook call for 'ERP助理' succeeded.
2025-09-19 10:06:08,647 - INFO - User 'leot' querying 'meeting': '' with file: C:/Users/leot/Documents/20231024-AR發票.mp4
2025-09-19 10:06:38,391 - ERROR - Webhook call for '會議助理' failed: Expecting value: line 1 column 1 (char 0)
Traceback (most recent call last):
  File "C:\Users\leot\AppData\Local\Programs\Python\Python313\Lib\site-packages\requests\models.py", line 974, in json
    return complexjson.loads(self.text, **kwargs)
           ~~~~~~~~~~~~~~~~~^^^^^^^^^^^^^^^^^^^^^
  File "C:\Users\leot\AppData\Local\Programs\Python\Python313\Lib\json\__init__.py", line 346, in loads
    return _default_decoder.decode(s)
           ~~~~~~~~~~~~~~~~~~~~~~~^^^
  File "C:\Users\leot\AppData\Local\Programs\Python\Python313\Lib\json\decoder.py", line 345, in decode
    obj, end = self.raw_decode(s, idx=_w(s, 0).end())
               ~~~~~~~~~~~~~~~^^^^^^^^^^^^^^^^^^^^^^^
  File "C:\Users\leot\AppData\Local\Programs\Python\Python313\Lib\json\decoder.py", line 363, in raw_decode
    raise JSONDecodeError("Expecting value", s, err.value) from None
json.decoder.JSONDecodeError: Expecting value: line 1 column 1 (char 0)

During handling of the above exception, another exception occurred:

Traceback (most recent call last):
  File "c:\Users\leot\Desktop\AD_Assistant\main.py", line 328, in perform_assistant_query
    response_data = response.json()
  File "C:\Users\leot\AppData\Local\Programs\Python\Python313\Lib\site-packages\requests\models.py", line 978, in json
    raise RequestsJSONDecodeError(e.msg, e.doc, e.pos)
requests.exceptions.JSONDecodeError: Expecting value: line 1 column 1 (char 0)
2025-09-19 10:11:25,864 - INFO - User 'leot' querying 'meeting': '' with file: C:/Users/leot/Downloads/20231024-AR發票.mp3
2025-09-19 10:11:29,133 - ERROR - Webhook call for '會議助理' failed: Expecting value: line 1 column 1 (char 0)
Traceback (most recent call last):
  File "C:\Users\leot\AppData\Local\Programs\Python\Python313\Lib\site-packages\requests\models.py", line 974, in json
    return complexjson.loads(self.text, **kwargs)
           ~~~~~~~~~~~~~~~~~^^^^^^^^^^^^^^^^^^^^^
  File "C:\Users\leot\AppData\Local\Programs\Python\Python313\Lib\json\__init__.py", line 346, in loads
    return _default_decoder.decode(s)
           ~~~~~~~~~~~~~~~~~~~~~~~^^^
  File "C:\Users\leot\AppData\Local\Programs\Python\Python313\Lib\json\decoder.py", line 345, in decode
    obj, end = self.raw_decode(s, idx=_w(s, 0).end())
               ~~~~~~~~~~~~~~~^^^^^^^^^^^^^^^^^^^^^^^
  File "C:\Users\leot\AppData\Local\Programs\Python\Python313\Lib\json\decoder.py", line 363, in raw_decode
    raise JSONDecodeError("Expecting value", s, err.value) from None
json.decoder.JSONDecodeError: Expecting value: line 1 column 1 (char 0)

During handling of the above exception, another exception occurred:

Traceback (most recent call last):
  File "c:\Users\leot\Desktop\AD_Assistant\main.py", line 328, in perform_assistant_query
    response_data = response.json()
  File "C:\Users\leot\AppData\Local\Programs\Python\Python313\Lib\site-packages\requests\models.py", line 978, in json
    raise RequestsJSONDecodeError(e.msg, e.doc, e.pos)
requests.exceptions.JSONDecodeError: Expecting value: line 1 column 1 (char 0)
2025-09-19 10:15:34,612 - INFO - User 'leot' querying 'meeting': '' with file: C:/Users/leot/Downloads/20231024-AR發票.mp3
2025-09-19 10:15:37,872 - ERROR - Webhook call for '會議助理' failed: Expecting value: line 1 column 1 (char 0)
Traceback (most recent call last):
  File "C:\Users\leot\AppData\Local\Programs\Python\Python313\Lib\site-packages\requests\models.py", line 974, in json
    return complexjson.loads(self.text, **kwargs)
           ~~~~~~~~~~~~~~~~~^^^^^^^^^^^^^^^^^^^^^
  File "C:\Users\leot\AppData\Local\Programs\Python\Python313\Lib\json\__init__.py", line 346, in loads
    return _default_decoder.decode(s)
           ~~~~~~~~~~~~~~~~~~~~~~~^^^
  File "C:\Users\leot\AppData\Local\Programs\Python\Python313\Lib\json\decoder.py", line 345, in decode
    obj, end = self.raw_decode(s, idx=_w(s, 0).end())
               ~~~~~~~~~~~~~~~^^^^^^^^^^^^^^^^^^^^^^^
  File "C:\Users\leot\AppData\Local\Programs\Python\Python313\Lib\json\decoder.py", line 363, in raw_decode
    raise JSONDecodeError("Expecting value", s, err.value) from None
json.decoder.JSONDecodeError: Expecting value: line 1 column 1 (char 0)

During handling of the above exception, another exception occurred:

Traceback (most recent call last):
  File "c:\Users\leot\Desktop\AD_Assistant\main.py", line 328, in perform_assistant_query
    response_data = response.json()
  File "C:\Users\leot\AppData\Local\Programs\Python\Python313\Lib\site-packages\requests\models.py", line 978, in json
    raise RequestsJSONDecodeError(e.msg, e.doc, e.pos)
requests.exceptions.JSONDecodeError: Expecting value: line 1 column 1 (char 0)
2025-09-19 10:17:39,668 - INFO - User 'leot' querying 'meeting': '' with file: C:/Users/leot/Downloads/20231024-AR發票.mp3
2025-09-19 10:17:42,912 - ERROR - Webhook call for '會議助理' failed: Expecting value: line 1 column 1 (char 0)
Traceback (most recent call last):
  File "C:\Users\leot\AppData\Local\Programs\Python\Python313\Lib\site-packages\requests\models.py", line 974, in json
    return complexjson.loads(self.text, **kwargs)
           ~~~~~~~~~~~~~~~~~^^^^^^^^^^^^^^^^^^^^^
  File "C:\Users\leot\AppData\Local\Programs\Python\Python313\Lib\json\__init__.py", line 346, in loads
    return _default_decoder.decode(s)
           ~~~~~~~~~~~~~~~~~~~~~~~^^^
  File "C:\Users\leot\AppData\Local\Programs\Python\Python313\Lib\json\decoder.py", line 345, in decode
    obj, end = self.raw_decode(s, idx=_w(s, 0).end())
               ~~~~~~~~~~~~~~~^^^^^^^^^^^^^^^^^^^^^^^
  File "C:\Users\leot\AppData\Local\Programs\Python\Python313\Lib\json\decoder.py", line 363, in raw_decode
    raise JSONDecodeError("Expecting value", s, err.value) from None
json.decoder.JSONDecodeError: Expecting value: line 1 column 1 (char 0)

During handling of the above exception, another exception occurred:

Traceback (most recent call last):
  File "c:\Users\leot\Desktop\AD_Assistant\main.py", line 328, in perform_assistant_query
    response_data = response.json()
  File "C:\Users\leot\AppData\Local\Programs\Python\Python313\Lib\site-packages\requests\models.py", line 978, in json
    raise RequestsJSONDecodeError(e.msg, e.doc, e.pos)
requests.exceptions.JSONDecodeError: Expecting value: line 1 column 1 (char 0)
2025-09-19 10:29:20,388 - INFO - User 'leot' querying 'meeting': '' with file: C:/Users/leot/Downloads/20231024-AR發票.mp3
2025-09-19 10:29:23,505 - ERROR - Webhook call for '會議助理' failed: Expecting value: line 1 column 1 (char 0)
Traceback (most recent call last):
  File "C:\Users\leot\AppData\Local\Programs\Python\Python313\Lib\site-packages\requests\models.py", line 974, in json
    return complexjson.loads(self.text, **kwargs)
           ~~~~~~~~~~~~~~~~~^^^^^^^^^^^^^^^^^^^^^
  File "C:\Users\leot\AppData\Local\Programs\Python\Python313\Lib\json\__init__.py", line 346, in loads
    return _default_decoder.decode(s)
           ~~~~~~~~~~~~~~~~~~~~~~~^^^
  File "C:\Users\leot\AppData\Local\Programs\Python\Python313\Lib\json\decoder.py", line 345, in decode
    obj, end = self.raw_decode(s, idx=_w(s, 0).end())
               ~~~~~~~~~~~~~~~^^^^^^^^^^^^^^^^^^^^^^^
  File "C:\Users\leot\AppData\Local\Programs\Python\Python313\Lib\json\decoder.py", line 363, in raw_decode
    raise JSONDecodeError("Expecting value", s, err.value) from None
json.decoder.JSONDecodeError: Expecting value: line 1 column 1 (char 0)

During handling of the above exception, another exception occurred:

Traceback (most recent call last):
  File "c:\Users\leot\Desktop\AD_Assistant\main.py", line 328, in perform_assistant_query
    response_data = response.json()
  File "C:\Users\leot\AppData\Local\Programs\Python\Python313\Lib\site-packages\requests\models.py", line 978, in json
    raise RequestsJSONDecodeError(e.msg, e.doc, e.pos)
requests.exceptions.JSONDecodeError: Expecting value: line 1 column 1 (char 0)
2025-09-19 10:33:13,884 - INFO - User 'leot' querying 'meeting': '' with file: C:/Users/leot/Downloads/20231024-AR發票.mp3
2025-09-19 10:35:23,950 - ERROR - Webhook call for '會議助理' failed: HTTPConnectionPool(host='192.168.88.43', port=5678): Read timed out. (read timeout=130)
Traceback (most recent call last):
  File "C:\Users\leot\AppData\Local\Programs\Python\Python313\Lib\site-packages\urllib3\connectionpool.py", line 534, in _make_request
    response = conn.getresponse()
  File "C:\Users\leot\AppData\Local\Programs\Python\Python313\Lib\site-packages\urllib3\connection.py", line 516, in getresponse
    httplib_response = super().getresponse()
  File "C:\Users\leot\AppData\Local\Programs\Python\Python313\Lib\http\client.py", line 1430, in getresponse
    response.begin()
    ~~~~~~~~~~~~~~^^
  File "C:\Users\leot\AppData\Local\Programs\Python\Python313\Lib\http\client.py", line 331, in begin
    version, status, reason = self._read_status()
                              ~~~~~~~~~~~~~~~~~^^
  File "C:\Users\leot\AppData\Local\Programs\Python\Python313\Lib\http\client.py", line 292, in _read_status
    line = str(self.fp.readline(_MAXLINE + 1), "iso-8859-1")
               ~~~~~~~~~~~~~~~~^^^^^^^^^^^^^^
  File "C:\Users\leot\AppData\Local\Programs\Python\Python313\Lib\socket.py", line 719, in readinto
    return self._sock.recv_into(b)
           ~~~~~~~~~~~~~~~~~~~~^^^
TimeoutError: timed out

The above exception was the direct cause of the following exception:

Traceback (most recent call last):
  File "C:\Users\leot\AppData\Local\Programs\Python\Python313\Lib\site-packages\requests\adapters.py", line 667, in send
    resp = conn.urlopen(
        method=request.method,
    ...<9 lines>...
        chunked=chunked,
    )
  File "C:\Users\leot\AppData\Local\Programs\Python\Python313\Lib\site-packages\urllib3\connectionpool.py", line 841, in urlopen
    retries = retries.increment(
        method, url, error=new_e, _pool=self, _stacktrace=sys.exc_info()[2]
    )
  File "C:\Users\leot\AppData\Local\Programs\Python\Python313\Lib\site-packages\urllib3\util\retry.py", line 474, in increment
    raise reraise(type(error), error, _stacktrace)
          ~~~~~~~^^^^^^^^^^^^^^^^^^^^^^^^^^^^^^^^^
  File "C:\Users\leot\AppData\Local\Programs\Python\Python313\Lib\site-packages\urllib3\util\util.py", line 39, in reraise
    raise value
  File "C:\Users\leot\AppData\Local\Programs\Python\Python313\Lib\site-packages\urllib3\connectionpool.py", line 787, in urlopen
    response = self._make_request(
        conn,
    ...<10 lines>...
        **response_kw,
    )
  File "C:\Users\leot\AppData\Local\Programs\Python\Python313\Lib\site-packages\urllib3\connectionpool.py", line 536, in _make_request
    self._raise_timeout(err=e, url=url, timeout_value=read_timeout)
    ~~~~~~~~~~~~~~~~~~~^^^^^^^^^^^^^^^^^^^^^^^^^^^^^^^^^^^^^^^^^^^^
  File "C:\Users\leot\AppData\Local\Programs\Python\Python313\Lib\site-packages\urllib3\connectionpool.py", line 367, in _raise_timeout
    raise ReadTimeoutError(
        self, url, f"Read timed out. (read timeout={timeout_value})"
    ) from err
urllib3.exceptions.ReadTimeoutError: HTTPConnectionPool(host='192.168.88.43', port=5678): Read timed out. (read timeout=130)

During handling of the above exception, another exception occurred:

Traceback (most recent call last):
  File "c:\Users\leot\Desktop\AD_Assistant\main.py", line 316, in perform_assistant_query
    response = requests.post(webhook_url, files=files, data=payload, timeout=130)
  File "C:\Users\leot\AppData\Local\Programs\Python\Python313\Lib\site-packages\requests\api.py", line 115, in post
    return request("post", url, data=data, json=json, **kwargs)
  File "C:\Users\leot\AppData\Local\Programs\Python\Python313\Lib\site-packages\requests\api.py", line 59, in request
    return session.request(method=method, url=url, **kwargs)
           ~~~~~~~~~~~~~~~^^^^^^^^^^^^^^^^^^^^^^^^^^^^^^^^^^
  File "C:\Users\leot\AppData\Local\Programs\Python\Python313\Lib\site-packages\requests\sessions.py", line 589, in request
    resp = self.send(prep, **send_kwargs)
  File "C:\Users\leot\AppData\Local\Programs\Python\Python313\Lib\site-packages\requests\sessions.py", line 703, in send
    r = adapter.send(request, **kwargs)
  File "C:\Users\leot\AppData\Local\Programs\Python\Python313\Lib\site-packages\requests\adapters.py", line 713, in send
    raise ReadTimeout(e, request=request)
requests.exceptions.ReadTimeout: HTTPConnectionPool(host='192.168.88.43', port=5678): Read timed out. (read timeout=130)
2025-09-19 10:51:59,290 - INFO - User 'leot' querying 'erp': '如何設定自動發貨?' with file: None
2025-09-19 10:52:28,285 - INFO - Webhook call for 'ERP助理' succeeded.
2025-09-19 10:53:07,897 - INFO - User 'leot' querying 'erp': '為何某些倉庫會自動發貨?' with file: None
2025-09-19 10:53:49,282 - INFO - Webhook call for 'ERP助理' succeeded.
2025-09-19 11:20:16,858 - INFO - User 'leot' closed application.
2025-09-19 11:20:20,725 - INFO - ================ Application Started ================
2025-09-19 13:22:49,186 - INFO - ================ Application Started ================
2025-09-19 13:23:31,599 - INFO - ================ Application Started ================
2025-09-19 13:23:41,279 - INFO - User 'leot' is attempting to log in.
2025-09-19 13:23:41,406 - INFO - User 'leot' logged in successfully. Groups: ['LCConfidential', 'LCIT']
2025-09-19 13:23:48,037 - INFO - User 'leot' closed application.
2025-09-19 13:28:11,575 - INFO - ================ Application Started ================
2025-09-19 13:28:18,360 - INFO - User 'leot' is attempting to log in.
2025-09-19 13:28:18,456 - INFO - User 'leot' logged in successfully. Groups: ['LCConfidential', 'LCIT']
2025-09-19 13:32:58,715 - INFO - User 'leot' closed application.
2025-09-19 14:20:57,043 - INFO - ================ Application Started ================
